Workbook

Sheet README
A1: Tracker development charts: data and Excel charts
A2: One sheet per slide chart (01-07), data on the left, chart on the right. Footnote under each table names the source.
A3: Black numbers are copied from the bench logs (docs/*.md) or raw CSVs; formula cells (two-box of active, histogram counts, totals) recalculate.
A4: Raw recordings for 01/02 (22-23 Sep) are lost: results/*.csv was gitignored. Their numbers come from the bench logs only.
A5: Charts 03, 05, 06 are simulation results, not hardware. Keep that note on the slide.
A6: Raw sheets: raw_reacquire (one row per loss, chart 04), raw_stand_bench (chart 05/06), raw_commits (chart 07).
A7: Regenerate CSVs: docs/graph_v2/data/*.csv. PNG versions: python3 docs/graph_v2/make_graphs.py
A8: Sheets 08-11: distributions and tests (match PNG charts 08-11). Formulas read raw_reacquire, raw_stand_bench, raw_jump.
A9: 08 Latency dist and 09 Reliability are hardware (field, three boxes); 10 Stand dist and 11 Jump dist are simulation.
A10: Typed numbers on those sheets (bootstrap CI, permutation, Mann-Whitney, Levene, Shapiro p) come from scipy in make_graphs.py; the note beside each says so.

Sheet 01 Coverage
A1: Run | B1: Date | C1: Player_on_screen_pct | D1: Two_box_pct_of_spots | E1: Recording | F1: Window_s | G1: Fixes_per_s | H1: Source | I1: Two_box_pct_of_active
A2: Run 10 | B2: 2026-09-22 | C2: 61 | E2: bench-live10 | F2: whole | G2: 4.3 | H2: docs/mvp1-bench-log-2026-09-22.md:51 | I2: =IF(D2="","",ROUND(C2*D2/100,0))
A3: Run 15 | B3: 2026-09-22 | C3: 75 | E3: bench-live15 | F3: whole | G3: 4.9 | H3: docs/mvp1-bench-log-2026-09-22.md:53 | I3: =IF(D3="","",ROUND(C3*D3/100,0))
A4: Run 18 | B4: 2026-09-22 | C4: 50 | E4: bench-live18 | F4: whole | G4: 4.8 | H4: docs/mvp1-bench-log-2026-09-22.md:55 | I4: =IF(D4="","",ROUND(C4*D4/100,0))
A5: Paired | B5: 2026-09-23 | C5: 14 | E5: uni-field15-run2 | F5: whole | G5: 2.6 | H5: docs/mvp1-bench-log-2026-09-23.md:42 | I5: =IF(D5="","",ROUND(C5*D5/100,0))
A6: Swarm 1 | B6: 2026-09-23 | C6: 92 | D6: 35 | E6: swarm-run1 | F6: whole | G6: 4.4 | H6: docs/mvp1-bench-log-2026-09-23.md:43 | I6: =IF(D6="","",ROUND(C6*D6/100,0)) -> 32
A7: Swarm 2 | B7: 2026-09-23 | C7: 94 | D7: 62 | E7: swarm-run2 | F7: 415-483 | G7: 6.3 | H7: docs/mvp1-bench-log-2026-09-23.md:45 | I7: =IF(D7="","",ROUND(C7*D7/100,0)) -> 58
A8: Swarm 3 | B8: 2026-09-23 | C8: 89 | D8: 68 | E8: swarm-run3 | F8: 40-266 | G8: 6.6 | H8: docs/mvp1-bench-log-2026-09-23.md:47 | I8: =IF(D8="","",ROUND(C8*D8/100,0)) -> 61
A10: Two-box % of spots = share of on-screen time where both boxes agreed within 0.30 m. Column I = C x D / 100 (share of active time). Swarm 2/3 are time windows, not whole runs.

Sheet 02 Losses
A1: Run | B1: Situation | C1: Losses_per_min | D1: Reacquire_median_s | E1: Reacquire_p90_s | F1: Jitter_x_cm | G1: Jitter_y_cm | H1: Source
A2: Paired | B2: Paired tracker | C2: 17.6 | D2: 4.4 | E2: 12.5 | F2: 0.3 | G2: 0.5 | H2: docs/mvp1-bench-log-2026-09-23.md
A3: Swarm 1 | B3: First swarm run | C3: 5.7 | D3: 0.4 | E3: 2 | F3: 6.2 | G3: 6.2 | H3: docs/mvp1-bench-log-2026-09-23.md
A4: Swarm 2 | B4: Box 1 levelled | C4: 2.6 | D4: 1.3 | E4: 1.9 | F4: 3.8 | G4: 5.6 | H4: docs/mvp1-bench-log-2026-09-23.md
A5: Swarm 3 | B5: No prediction | C5: 1.3 | D5: 1.4 | E5: 15.6 | F5: 2.1 | G5: 2.4 | H5: docs/mvp1-bench-log-2026-09-23.md
A7: Source: docs/mvp1-bench-log-2026-09-23.md. Full segment table on sheet 02b.

Sheet 02b Segments
A1: Recording | B1: Window_s | C1: Situation | D1: Dot_pct | E1: Two_box_pct_of_spots | F1: Fixes_per_s | G1: Jitter_x_cm | H1: Jitter_y_cm | I1: Losses_per_min | J1: Reacquire_median_s | K1: Reacquire_p90_s | L1: Echo_node0_pct | M1: Echo_node1_pct | N1: Source
A2: uni-field15-run2 | B2: whole | C2: paired tracker, 1.5 m apart | D2: 14 | F2: 2.6 | G2: 0.3 | H2: 0.5 | I2: 17.6 | J2: 4.4 | K2: 12.5 | N2: docs/mvp1-bench-log-2026-09-23.md:42
A3: swarm-run1 | B3: whole | C3: first swarm run, walking | D3: 92 | E3: 35 | F3: 4.4 | G3: 6.2 | H3: 6.2 | I3: 5.7 | J3: 0.4 | K3: 2 | L3: 73 | M3: 45 | N3: docs/mvp1-bench-log-2026-09-23.md:43
A4: swarm-run2 | B4: 0-58 | C4: box 1 tilted (floor echo) | D4: 89 | E4: 25 | F4: 4 | G4: 5.7 | H4: 7.2 | I4: 10.3 | J4: 0.5 | K4: 1.1 | L4: 74 | M4: 35 | N4: docs/mvp1-bench-log-2026-09-23.md:44
A5: swarm-run2 | B5: 415-483 | C5: box 1 straightened | D5: 94 | E5: 62 | F5: 6.3 | G5: 3.8 | H5: 5.6 | I5: 2.6 | J5: 1.3 | K5: 1.9 | L5: 68 | M5: 85 | N5: docs/mvp1-bench-log-2026-09-23.md:45
A6: swarm-run2 | B6: 670-864 | C6: long walk, with prediction | D6: 88 | E6: 39 | F6: 4.2 | G6: 7.3 | H6: 5.1 | I6: 3.4 | J6: 0.4 | K6: 3.8 | L6: 56 | M6: 66 | N6: docs/mvp1-bench-log-2026-09-23.md:46
A7: swarm-run3 | B7: 40-266 | C7: prediction removed | D7: 89 | E7: 68 | F7: 6.6 | G7: 2.1 | H7: 2.4 | I7: 1.3 | J7: 1.4 | K7: 15.6 | L7: 75 | M7: 74 | N7: docs/mvp1-bench-log-2026-09-23.md:47
A8: swarm-run3 | B8: 400-692 | C8: after box 0 USB re-plug | D8: 73 | E8: 31 | F8: 4.9 | G8: 3.1 | H8: 3.9 | I8: 4.3 | J8: 0.8 | K8: 7.4 | L8: 40 | M8: 55 | N8: docs/mvp1-bench-log-2026-09-23.md:48
A10: Every segment of 23 Sep, including the weaker windows not in the chart.

Sheet 01b Bench runs
A1: Recording | B1: Situation | C1: Calibration | D1: Dot_pct | E1: Fixes_per_s | F1: Jitter_x_cm | G1: Jitter_y_cm | H1: Reacquire_median_s | I1: Reacquire_p90_s | J1: Source
A2: 15:53 | B2: first two-node attempt, no retry logic | C2: 0 of 3 sweeps completed | D2: 0 | J2: docs/mvp1-bench-log-2026-09-22.md:48
A3: bench-live2 | B3: retries added; right sensor mis-aimed | C3: 111/111 in 30 s | D3: 0 | J3: docs/mvp1-bench-log-2026-09-22.md:49
A4: bench-live5..9 | B4: travel widened, deeper field, ramp | C4: completed each time | D4: 0 | J4: docs/mvp1-bench-log-2026-09-22.md:50
A5: bench-live10 | B5: first lock, point-target model | C5: 138/138 in 32 s x2 | D5: 61 | E5: 4.3 | F5: 7.8 | G5: 3.2 | H5: 0.8 | I5: 0.9 | J5: docs/mvp1-bench-log-2026-09-22.md:51
A6: bench-live13 | B6: boxes reassembled, sensors blocked | C6: maps contaminated | D6: 0 | J6: docs/mvp1-bench-log-2026-09-22.md:52
A7: bench-live15 | B7: sensors outside boxes, body model | C7: 138/138 in 31 s | D7: 75 | E7: 4.9 | F7: 2.2 | G7: 0.7 | H7: 0.8 | I7: 10.5 | J7: docs/mvp1-bench-log-2026-09-22.md:53
A8: bench-live16 | B8: mirrored display, fast moves | C8: (reused) | D8: 47 | E8: 4.5 | F8: 3 | G8: 1.9 | H8: 1 | I8: 6.2 | J8: docs/mvp1-bench-log-2026-09-22.md:54
A9: bench-live18 | B9: grid, 200 s walking incl. edges | C9: (reused) | D9: 50 | E9: 4.8 | F9: 4.3 | G9: 3.2 | H9: 0.8 | I9: 7.4 | J9: docs/mvp1-bench-log-2026-09-22.md:55
A11: Every run of 22 Sep (bench), including run 16 (not in the chart).

Sheet 03 Jump sim
A1: Jump | B1: Before_s | C1: Search_s | D1: Search_hint_right_s | E1: Search_hint_wrong_s | F1: Source
A2: 1 → 3 | B2: 3.69 | C2: 1.49 | D2: 0.84 | E2: 1.42 | F2: docs/jump-bench-2026-10-02.md (median of 20 trials)
A3: 3 → 1 | B3: 6.71 | C3: 1.35 | D3: 0.88 | E3: 1.43 | F3: docs/jump-bench-2026-10-02.md (median of 20 trials)
A4: 1 → 3 far | B4: 3.35 | C4: 1.45 | D4: 0.84 | E4: 1.72 | F4: docs/jump-bench-2026-10-02.md (median of 20 trials)
A5: 3 → 1 far | B5: 9.12 | C5: 1.34 | D5: 0.9 | E5: 1.43 | F5: docs/jump-bench-2026-10-02.md (median of 20 trials)
A6: All skips, 95th pct | B6: 9.22 | C6: 1.89 | D6: 0.94 | E6: 1.81 | F6: docs/jump-bench-2026-10-02.md:68-71
A8: SIMULATION. Median of 20 trials, seconds to first fix. Raw: data/raw/jump-bench-2026-10-02.csv.

Sheet raw_reacquire
A1: version | B1: reacquire_s | C1: ln_reacquire
A2: V1 | B2: 6.13 | C2: =LN(B2) -> 1.8131947
A3: V1 | B3: 1.54 | C3: =LN(B3) -> 0.43178242
A4: V1 | B4: 0.1 | C4: =LN(B4) -> -2.3025851
A5: V1 | B5: 0.1 | C5: =LN(B5) -> -2.3025851
A6: V1 | B6: 0.61 | C6: =LN(B6) -> -0.49429632
A7: V1 | B7: 0.61 | C7: =LN(B7) -> -0.49429632
A8: V1 | B8: 0.61 | C8: =LN(B8) -> -0.49429632
A9: V1 | B9: 2.86 | C9: =LN(B9) -> 1.0508216
A10: V1 | B10: 0.3 | C10: =LN(B10) -> -1.2039728
A11: V1 | B11: 0.2 | C11: =LN(B11) -> -1.6094379
A12: V1 | B12: 0.71 | C12: =LN(B12) -> -0.34249031
A13: V1 | B13: 1.63 | C13: =LN(B13) -> 0.48858001
... A108: V2 | B108: 0.1 | C108: =LN(B108) -> -2.3025851
A110: One row per tracking loss. V1 = jump-v1-3.csv, V2 = jump-v2-1.csv.

Sheet 04 V1 vs V2
A1: Reacquire_bin_s | B1: V1_count | C1: V2_count | D1: V1_pct | E1: V2_pct | F1: Source
A2: < 0.25 | B2: =COUNTIFS(raw_reacquire!$A$2:$A$108,"V1",raw_reacquire!$B$2:$B$108,">=0",raw_reacquire!$B$2:$B$108,"<0.25") -> 25 | C2: =COUNTIFS(raw_reacquire!$A$2:$A$108,"V2",raw_reacquire!$B$2:$B$108,">=0",raw_reacquire!$B$2:$B$108,"<0.25") -> 19 | D2: =ROUND(100*B2/SUM($B$2:$B$7),1) -> 35.7 | E2: =ROUND(100*C2/SUM($C$2:$C$7),1) -> 51.4 | F2: data/raw/reacquire_losses.csv
A3: 0.25–0.5 | B3: =COUNTIFS(raw_reacquire!$A$2:$A$108,"V1",raw_reacquire!$B$2:$B$108,">=0.25",raw_reacquire!$B$2:$B$108,"<0.5") -> 8 | C3: =COUNTIFS(raw_reacquire!$A$2:$A$108,"V2",raw_reacquire!$B$2:$B$108,">=0.25",raw_reacquire!$B$2:$B$108,"<0.5") -> 7 | D3: =ROUND(100*B3/SUM($B$2:$B$7),1) -> 11.4 | E3: =ROUND(100*C3/SUM($C$2:$C$7),1) -> 18.9 | F3: data/raw/reacquire_losses.csv
A4: 0.5–1 | B4: =COUNTIFS(raw_reacquire!$A$2:$A$108,"V1",raw_reacquire!$B$2:$B$108,">=0.5",raw_reacquire!$B$2:$B$108,"<1") -> 23 | C4: =COUNTIFS(raw_reacquire!$A$2:$A$108,"V2",raw_reacquire!$B$2:$B$108,">=0.5",raw_reacquire!$B$2:$B$108,"<1") -> 5 | D4: =ROUND(100*B4/SUM($B$2:$B$7),1) -> 32.9 | E4: =ROUND(100*C4/SUM($C$2:$C$7),1) -> 13.5 | F4: data/raw/reacquire_losses.csv
A5: 1–2 | B5: =COUNTIFS(raw_reacquire!$A$2:$A$108,"V1",raw_reacquire!$B$2:$B$108,">=1",raw_reacquire!$B$2:$B$108,"<2") -> 7 | C5: =COUNTIFS(raw_reacquire!$A$2:$A$108,"V2",raw_reacquire!$B$2:$B$108,">=1",raw_reacquire!$B$2:$B$108,"<2") -> 5 | D5: =ROUND(100*B5/SUM($B$2:$B$7),1) -> 10 | E5: =ROUND(100*C5/SUM($C$2:$C$7),1) -> 13.5 | F5: data/raw/reacquire_losses.csv
A6: 2–3 | B6: =COUNTIFS(raw_reacquire!$A$2:$A$108,"V1",raw_reacquire!$B$2:$B$108,">=2",raw_reacquire!$B$2:$B$108,"<3") -> 4 | C6: =COUNTIFS(raw_reacquire!$A$2:$A$108,"V2",raw_reacquire!$B$2:$B$108,">=2",raw_reacquire!$B$2:$B$108,"<3") -> 1 | D6: =ROUND(100*B6/SUM($B$2:$B$7),1) -> 5.7 | E6: =ROUND(100*C6/SUM($C$2:$C$7),1) -> 2.7 | F6: data/raw/reacquire_losses.csv
A7: ≥ 3 | B7: =COUNTIFS(raw_reacquire!$A$2:$A$108,"V1",raw_reacquire!$B$2:$B$108,">=3",raw_reacquire!$B$2:$B$108,"<1000000000.0") -> 3 | C7: =COUNTIFS(raw_reacquire!$A$2:$A$108,"V2",raw_reacquire!$B$2:$B$108,">=3",raw_reacquire!$B$2:$B$108,"<1000000000.0") -> 0 | D7: =ROUND(100*B7/SUM($B$2:$B$7),1) -> 4.3 | E7: =ROUND(100*C7/SUM($C$2:$C$7),1) -> 0 | F7: data/raw/reacquire_losses.csv
A8: Total | B8: =SUM(B2:B7) -> 70 | C8: =SUM(C2:C7) -> 37
A9: Counts are COUNTIFS on raw_reacquire; % = count / total losses of that version.

Sheet 04b Summary
A1: Metric | B1: V1 | C1: V2 | D1: p_value
A2: Tracking time recorded (s) | B2: 305 | C2: 112
A3: Losses (n) | B3: 70 | C3: 37
A4: Losses per tracking minute | B4: 13.8 | C4: 19.9
A5: Fix from 2+ boxes (%) | B5: 70 | C5: 67
A6: Reacquire median (s) | B6: 0.51 | C6: 0.21 | D6: 0.016
A7: Reacquire mean (s) | B7: 0.79 | C7: 0.47 | D7: 0.032
A8: Reacquire 90th pct (s) | B8: 2.25 | C8: 1.12
A9: Reacquire longest (s) | B9: 6.13 | C9: 2.45
A10: Losses > 1 s (%) | B10: 20 | C10: 16
A11: Losses > 2 s (%) | B11: 10 | C11: 3 | D11: 0.163
A12: Losses > 3 s (%) | B12: 4 | C12: 0
A14: Source: results/report/reacquire_table.md. p = one-sided permutation test, 20 000 shuffles.

Sheet 05 Stand steps
A1: Step | B1: Change | C1: Losses_per_min | D1: Jumps_per_min | E1: On_hole_pct | F1: Source
A2: Before | B2: V2 as of 3191700 | C2: 12.4 | D2: 3.7 | E2: 87 | F2: docs/stand-bench-2026-10-05.md:120-125
A3: + Band | B3: Static echo as a 10° band | C3: 10.7 | D3: 0.3 | E3: 95 | F3: docs/stand-bench-2026-10-05.md:120-125
A4: + Agreement | B4: Beam check and outvote | C4: 10.4 | D4: 0 | E4: 95 | F4: docs/stand-bench-2026-10-05.md:120-125
A5: + Keep echo | B5: Keep last echo, 16° | C5: 1.2 | D5: 0 | E5: 99 | F5: docs/stand-bench-2026-10-05.md:120-125
A7: SIMULATION. docs/stand-bench-2026-10-05.md, 15 holes x 3 trials x 30 s.

Sheet 06 Per hole
A1: Hole_x_m | B1: Hole_y_m | C1: Hole | D1: Losses_per_min_before | E1: Losses_per_min_after | F1: Jumps_per_min_before | G1: Jumps_per_min_after | H1: On_hole_pct_before | I1: On_hole_pct_after | J1: Source
A2: 0.25 | B2: 1.1 | C2: (0.25, 1.10) | D2: 20.7 | E2: 2.7 | F2: 4.7 | G2: 0 | H2: 73 | I2: 100 | J2: docs/stand-bench-2026-10-05.md:90-106
A3: 0.5 | B3: 1.1 | C3: (0.50, 1.10) | D3: 16.7 | E3: 1.3 | F3: 2 | G3: 0 | H3: 86 | I3: 98 | J3: docs/stand-bench-2026-10-05.md:90-106
A4: 0.75 | B4: 1.1 | C4: (0.75, 1.10) | D4: 18 | E4: 4.7 | F4: 0 | G4: 0 | H4: 91 | I4: 98 | J4: docs/stand-bench-2026-10-05.md:90-106
A5: 1 | B5: 1.1 | C5: (1.00, 1.10) | D5: 12 | E5: 2.7 | F5: 2.7 | G5: 0 | H5: 87 | I5: 99 | J5: docs/stand-bench-2026-10-05.md:90-106
A6: 1.25 | B6: 1.1 | C6: (1.25, 1.10) | D6: 17.3 | E6: 2.7 | F6: 5.3 | G6: 0 | H6: 79 | I6: 98 | J6: docs/stand-bench-2026-10-05.md:90-106
A7: 0.25 | B7: 1.42 | C7: (0.25, 1.42) | D7: 18 | E7: 0.7 | F7: 8 | G7: 0 | H7: 78 | I7: 99 | J7: docs/stand-bench-2026-10-05.md:90-106
A8: 0.5 | B8: 1.42 | C8: (0.50, 1.42) | D8: 14.7 | E8: 0.7 | F8: 10 | G8: 0 | H8: 81 | I8: 100 | J8: docs/stand-bench-2026-10-05.md:90-106
A9: 0.75 | B9: 1.42 | C9: (0.75, 1.42) | D9: 6.7 | E9: 0.7 | F9: 0.7 | G9: 0 | H9: 98 | I9: 100 | J9: docs/stand-bench-2026-10-05.md:90-106
A10: 1 | B10: 1.42 | C10: (1.00, 1.42) | D10: 7.3 | E10: 0 | F10: 3.3 | G10: 0 | H10: 91 | I10: 98 | J10: docs/stand-bench-2026-10-05.md:90-106
A11: 1.25 | B11: 1.42 | C11: (1.25, 1.42) | D11: 16 | E11: 0 | F11: 8 | G11: 0 | H11: 80 | I11: 100 | J11: docs/stand-bench-2026-10-05.md:90-106
A12: 0.25 | B12: 1.74 | C12: (0.25, 1.74) | D12: 13.3 | E12: 0 | F12: 8.7 | G12: 0 | H12: 83 | I12: 100 | J12: docs/stand-bench-2026-10-05.md:90-106
A13: 0.5 | B13: 1.74 | C13: (0.50, 1.74) | D13: 8 | E13: 0.7 | F13: 0.7 | G13: 0 | H13: 94 | I13: 100 | J13: docs/stand-bench-2026-10-05.md:90-106
... A16: 1.25 | B16: 1.74 | C16: (1.25, 1.74) | D16: 6.7 | E16: 0 | F16: 2 | G16: 0 | H16: 96 | I16: 100 | J16: docs/stand-bench-2026-10-05.md:90-106
A18: SIMULATION. x from player's left, y from sensor line (m). Raw: raw_stand_bench.

Sheet raw_stand_bench
A1: variant | B1: hole_x_m | C1: hole_y_m | D1: seed | E1: losses_per_min | F1: jumps_per_min | G1: on_hole | H1: two_box | I1: shown | J1: median_error_m | K1: outvoted
A2: before | B2: 0.25 | C2: 1.1 | D2: 0 | E2: 18 | F2: 4 | G2: 0.775 | H2: 0.771 | I2: 0.917 | J2: 0.0003 | K2: 0
A3: before | B3: 0.25 | C3: 1.1 | D3: 1 | E3: 22 | F3: 4 | G3: 0.708 | H3: 0.642 | I3: 0.881 | J3: 0.0014 | K3: 0
A4: before | B4: 0.25 | C4: 1.1 | D4: 2 | E4: 22 | F4: 6 | G4: 0.693 | H4: 0.708 | I4: 0.888 | J4: 0.0034 | K4: 0
A5: before | B5: 0.5 | C5: 1.1 | D5: 0 | E5: 12 | F5: 0 | G5: 0.846 | H5: 0.774 | I5: 0.958 | J5: 0.0001 | K5: 0
A6: before | B6: 0.5 | C6: 1.1 | D6: 1 | E6: 26 | F6: 4 | G6: 0.842 | H6: 0.77 | I6: 0.942 | J6: 0.0017 | K6: 0
A7: before | B7: 0.5 | C7: 1.1 | D7: 2 | E7: 12 | F7: 2 | G7: 0.894 | H7: 0.809 | I7: 0.968 | J7: 0.0001 | K7: 0
A8: before | B8: 0.75 | C8: 1.1 | D8: 0 | E8: 16 | F8: 0 | G8: 0.881 | H8: 0.769 | I8: 0.958 | J8: 0.0009 | K8: 0
A9: before | B9: 0.75 | C9: 1.1 | D9: 1 | E9: 18 | F9: 0 | G9: 0.935 | H9: 0.835 | I9: 0.971 | J9: 0.0037 | K9: 0
A10: before | B10: 0.75 | C10: 1.1 | D10: 2 | E10: 20 | F10: 0 | G10: 0.916 | H10: 0.799 | I10: 0.946 | J10: 0.0033 | K10: 0
A11: before | B11: 1 | C11: 1.1 | D11: 0 | E11: 8 | F11: 4 | G11: 0.838 | H11: 0.842 | I11: 0.971 | J11: 0.0001 | K11: 0
A12: before | B12: 1 | C12: 1.1 | D12: 1 | E12: 14 | F12: 2 | G12: 0.876 | H12: 0.729 | I12: 0.97 | J12: 0.0001 | K12: 0
A13: before | B13: 1 | C13: 1.1 | D13: 2 | E13: 14 | F13: 2 | G13: 0.903 | H13: 0.809 | I13: 0.958 | J13: 0.0001 | K13: 0
... A91: after | B91: 1.25 | C91: 1.74 | D91: 2 | E91: 0 | F91: 0 | G91: 0.989 | H91: 0.972 | I91: 1 | J91: 0.0003 | K91: 0
A93: Per hole, per seed. losses_per_min etc. averaged over 3 seeds give sheet 06.

Sheet 07 Commits
A1: Day | B1: Tracker | C1: Firmware | D1: Tools, tests, config | E1: Docs, results | F1: Total | G1: Milestone
A2: 12 Sep | B2: 2 | C2: 0 | D2: 1 | E2: 1 | F2: =SUM(B2:E2) -> 4
A3: 22 Sep | B3: 2 | C3: 0 | D3: 0 | E3: 0 | F3: =SUM(B3:E3) -> 2 | G3: First lock
A4: 23 Sep | B4: 5 | C4: 0 | D4: 0 | E4: 1 | F4: =SUM(B4:E4) -> 6 | G4: Swarm tracker
A5: 24 Sep | B5: 0 | C5: 0 | D5: 0 | E5: 1 | F5: =SUM(B5:E5) -> 1
A6: 29 Sep | B6: 4 | C6: 6 | D6: 3 | E6: 2 | F6: =SUM(B6:E6) -> 15 | G6: Third box
A7: 30 Sep | B7: 0 | C7: 1 | D7: 0 | E7: 0 | F7: =SUM(B7:E7) -> 1
A8: 1 Oct | B8: 0 | C8: 2 | D8: 3 | E8: 2 | F8: =SUM(B8:E8) -> 7
A9: 2 Oct | B9: 1 | C9: 0 | D9: 1 | E9: 1 | F9: =SUM(B9:E9) -> 3 | G9: Search after loss
A10: 5 Oct | B10: 1 | C10: 0 | D10: 0 | E10: 1 | F10: =SUM(B10:E10) -> 2 | G10: Ghost-echo fix
A11: Total | B11: =SUM(B2:B10) -> 15 | C11: =SUM(C2:C10) -> 9 | D11: =SUM(D2:D10) -> 8 | E11: =SUM(E2:E10) -> 9 | F11: =SUM(F2:F10) -> 41
A13: Source: git log, merges left out. Every commit on raw_commits.

Sheet raw_commits
A1: Date | B1: Commit | C1: Area | D1: Subject
A2: 2026-09-12 08:25 | B2: a384f68 | C2: Tools, tests, config | D2: chore: establish project baseline and two-node architecture
A3: 2026-09-12 08:31 | B3: 43d32f4 | C3: Tracker | D3: feat: add coordinated ESP32 sensor and servo firmware
A4: 2026-09-12 08:39 | B4: fabedae | C4: Tracker | D4: feat: implement hardware tracking and black-screen dot visualizer
A5: 2026-09-12 08:43 | B5: c25772a | C5: Docs, results | D5: docs: finalize tracker setup and refresh project graph
A6: 2026-09-22 23:57 | B6: 3433b79 | C6: Tracker | D6: feat: coordinated live tracker, TrackerNet profiles and field test docs
A7: 2026-09-22 23:57 | B7: 2df7385 | C7: Tracker | D7: feat: bench-proven tracking: robust calibration, smooth servos, body model, operator UI
A8: 2026-09-23 00:01 | B8: e517a3d | C8: Docs, results | D8: docs: add README_1.html, an illustrated explainer of the two-servo tracker
A9: 2026-09-23 12:01 | B9: 3c15229 | C9: Tracker | D9: tracking: keep a confirm candidate through misses, 1 s recovery window, reason column
A10: 2026-09-23 13:33 | B10: 40f9f4e | C10: Tracker | D10: plumbing: allow more than two boxes in protocol, geometry, transport and CLI
A11: 2026-09-23 13:43 | B11: 1c9836b | C11: Tracker | D11: swarm: independent-sweep, leader-follower tracker for N boxes (whack/swarm.py)
A12: 2026-09-23 13:55 | B12: 3ebfc40 | C12: Tracker | D12: swarm: dead-zone alert, one-box fixes need a wide margin before "outside"
... A39: 2026-10-02 10:14 | B39: 9d551f9 | C39: Tools, tests, config | D39: tools: jump benchmark in the simulator, with the recorded results
A40: 2026-10-02 13:07 | B40: 3191700 | C40: Docs, results | D40: docs: commit hashes quoted in the bench logs
A41: 2026-10-05 03:34 | B41: aee8ef0 | C41: Tracker | D41: tracker: hold a player who stands still despite a static echo and missed pings
A42: 2026-10-05 03:39 | B42: 5674ee0 | C42: Docs, results | D42: results: V1 vs V2 reacquisition table and histogram for the report
A44: git log --no-merges, oldest first. Area from the commit prefix.

Sheet 08 Latency dist
A1: Bin_from_s | B1: Bin_to_s | C1: Bin | D1: V1_count | E1: V2_count | F1: V1_pct | G1: V2_pct | H1: V1_lognormal_fit_pct | I1: V2_lognormal_fit_pct
A2: 0.075 | B2: 0.15 | C2: 0.075–0.15 | D2: =COUNTIFS(raw_reacquire!$B$2:$B$71,">="&A2,raw_reacquire!$B$2:$B$71,"<"&B2) -> 15 | E2: =COUNTIFS(raw_reacquire!$B$72:$B$108,">="&A2,raw_reacquire!$B$72:$B$108,"<"&B2) -> 13 | F2: =ROUND(100*D2/$B$13,1) -> 21.4 | G2: =ROUND(100*E2/$C$13,1) -> 35.1 | H2: =ROUND(100*(NORMDIST(LN(B2),$B$18,$B$19,TRUE())-NORMDIST(LN(A2),$B$18,$B$19,TRUE())),1) -> 11.3 | I2: =ROUND(100*(NORMDIST(LN(B2),$C$18,$C$19,TRUE())-NORMDIST(LN(A2),$C$18,$C$19,TRUE())),1) -> 16.7
A3: 0.15 | B3: 0.3 | C3: 0.15–0.3 | D3: =COUNTIFS(raw_reacquire!$B$2:$B$71,">="&A3,raw_reacquire!$B$2:$B$71,"<"&B3) -> 10 | E3: =COUNTIFS(raw_reacquire!$B$72:$B$108,">="&A3,raw_reacquire!$B$72:$B$108,"<"&B3) -> 6 | F3: =ROUND(100*D3/$B$13,1) -> 14.3 | G3: =ROUND(100*E3/$C$13,1) -> 16.2 | H3: =ROUND(100*(NORMDIST(LN(B3),$B$18,$B$19,TRUE())-NORMDIST(LN(A3),$B$18,$B$19,TRUE())),1) -> 20.4 | I3: =ROUND(100*(NORMDIST(LN(B3),$C$18,$C$19,TRUE())-NORMDIST(LN(A3),$C$18,$C$19,TRUE())),1) -> 26.1
A4: 0.3 | B4: 0.6 | C4: 0.3–0.6 | D4: =COUNTIFS(raw_reacquire!$B$2:$B$71,">="&A4,raw_reacquire!$B$2:$B$71,"<"&B4) -> 15 | E4: =COUNTIFS(raw_reacquire!$B$72:$B$108,">="&A4,raw_reacquire!$B$72:$B$108,"<"&B4) -> 7 | F4: =ROUND(100*D4/$B$13,1) -> 21.4 | G4: =ROUND(100*E4/$C$13,1) -> 18.9 | H4: =ROUND(100*(NORMDIST(LN(B4),$B$18,$B$19,TRUE())-NORMDIST(LN(A4),$B$18,$B$19,TRUE())),1) -> 24.9 | I4: =ROUND(100*(NORMDIST(LN(B4),$C$18,$C$19,TRUE())-NORMDIST(LN(A4),$C$18,$C$19,TRUE())),1) -> 25.5
A5: 0.6 | B5: 1.2 | C5: 0.6–1.2 | D5: =COUNTIFS(raw_reacquire!$B$2:$B$71,">="&A5,raw_reacquire!$B$2:$B$71,"<"&B5) -> 19 | E5: =COUNTIFS(raw_reacquire!$B$72:$B$108,">="&A5,raw_reacquire!$B$72:$B$108,"<"&B5) -> 9 | F5: =ROUND(100*D5/$B$13,1) -> 27.1 | G5: =ROUND(100*E5/$C$13,1) -> 24.3 | H5: =ROUND(100*(NORMDIST(LN(B5),$B$18,$B$19,TRUE())-NORMDIST(LN(A5),$B$18,$B$19,TRUE())),1) -> 20.7 | I5: =ROUND(100*(NORMDIST(LN(B5),$C$18,$C$19,TRUE())-NORMDIST(LN(A5),$C$18,$C$19,TRUE())),1) -> 15.5
A6: 1.2 | B6: 2.4 | C6: 1.2–2.4 | D6: =COUNTIFS(raw_reacquire!$B$2:$B$71,">="&A6,raw_reacquire!$B$2:$B$71,"<"&B6) -> 7 | E6: =COUNTIFS(raw_reacquire!$B$72:$B$108,">="&A6,raw_reacquire!$B$72:$B$108,"<"&B6) -> 1 | F6: =ROUND(100*D6/$B$13,1) -> 10 | G6: =ROUND(100*E6/$C$13,1) -> 2.7 | H6: =ROUND(100*(NORMDIST(LN(B6),$B$18,$B$19,TRUE())-NORMDIST(LN(A6),$B$18,$B$19,TRUE())),1) -> 11.6 | I6: =ROUND(100*(NORMDIST(LN(B6),$C$18,$C$19,TRUE())-NORMDIST(LN(A6),$C$18,$C$19,TRUE())),1) -> 5.9
A7: 2.4 | B7: 4.8 | C7: 2.4–4.8 | D7: =COUNTIFS(raw_reacquire!$B$2:$B$71,">="&A7,raw_reacquire!$B$2:$B$71,"<"&B7) -> 3 | E7: =COUNTIFS(raw_reacquire!$B$72:$B$108,">="&A7,raw_reacquire!$B$72:$B$108,"<"&B7) -> 1 | F7: =ROUND(100*D7/$B$13,1) -> 4.3 | G7: =ROUND(100*E7/$C$13,1) -> 2.7 | H7: =ROUND(100*(NORMDIST(LN(B7),$B$18,$B$19,TRUE())-NORMDIST(LN(A7),$B$18,$B$19,TRUE())),1) -> 4.4 | I7: =ROUND(100*(NORMDIST(LN(B7),$C$18,$C$19,TRUE())-NORMDIST(LN(A7),$C$18,$C$19,TRUE())),1) -> 1.4
A8: 4.8 | B8: 9.6 | C8: 4.8–9.6 | D8: =COUNTIFS(raw_reacquire!$B$2:$B$71,">="&A8,raw_reacquire!$B$2:$B$71,"<"&B8) -> 1 | E8: =COUNTIFS(raw_reacquire!$B$72:$B$108,">="&A8,raw_reacquire!$B$72:$B$108,"<"&B8) -> 0 | F8: =ROUND(100*D8/$B$13,1) -> 1.4 | G8: =ROUND(100*E8/$C$13,1) -> 0 | H8: =ROUND(100*(NORMDIST(LN(B8),$B$18,$B$19,TRUE())-NORMDIST(LN(A8),$B$18,$B$19,TRUE())),1) -> 1.1 | I8: =ROUND(100*(NORMDIST(LN(B8),$C$18,$C$19,TRUE())-NORMDIST(LN(A8),$C$18,$C$19,TRUE())),1) -> 0.2
C9: Total | D9: =SUM(D2:D8) -> 70 | E9: =SUM(E2:E8) -> 37
A10: Bins double in width (equal on a log axis). Fit = share of a log-normal (normal distribution of ln(time), mean and SD below) falling in the bin. Times resolved to ~0.1 s, so 0.1 s is the floor.
A12: Statistic | B12: V1 | C12: V2 | D12: Note
A13: n (losses) | B13: =COUNT(raw_reacquire!$B$2:$B$71) -> 70 | C13: =COUNT(raw_reacquire!$B$72:$B$108) -> 37
A14: Median (s) | B14: =MEDIAN(raw_reacquire!$B$2:$B$71) -> 0.51 | C14: =MEDIAN(raw_reacquire!$B$72:$B$108) -> 0.21
A15: Median 95% CI low (s) | B15: 0.3 | C15: 0.1 | D15: Bootstrap, 20 000 resamples (make_graphs.py)
A16: Median 95% CI high (s) | B16: 0.61 | C16: 0.41 | D16: Bootstrap, 20 000 resamples (make_graphs.py)
A17: Mean (s) | B17: =AVERAGE(raw_reacquire!$B$2:$B$71) -> 0.78857143 | C17: =AVERAGE(raw_reacquire!$B$72:$B$108) -> 0.46972973
A18: Mean of ln(t) | B18: =AVERAGE(raw_reacquire!$C$2:$C$71) -> -0.84543651 | C18: =AVERAGE(raw_reacquire!$C$72:$C$108) -> -1.2402945 | D18: Log-normal location
A19: SD of ln(t) | B19: =STDEV(raw_reacquire!$C$2:$C$71) -> 1.0902346 | C19: =STDEV(raw_reacquire!$C$72:$C$108) -> 0.98935445 | D19: Log-normal scale
A20: SD (s) | B20: =STDEV(raw_reacquire!$B$2:$B$71) -> 1.0611974 | C20: =STDEV(raw_reacquire!$B$72:$B$108) -> 0.50345742
A21: Geometric mean (s) | B21: =EXP(B18) -> 0.42936989 | C21: =EXP(C18) -> 0.289299 | D21: exp(mean of ln t)
A22: 90th percentile (s) | B22: =SMALL(raw_reacquire!$B$2:$B$71,INT(B13*0.9)+1) -> 2.25 | C22: =SMALL(raw_reacquire!$B$72:$B$108,INT(C13*0.9)+1) -> 1.12 | D22: Same rule as reacquire_report.py
A23: Longest (s) | B23: =MAX(raw_reacquire!$B$2:$B$71) -> 6.13 | C23: =MAX(raw_reacquire!$B$72:$B$108) -> 2.45
A24: Median ratio V2 / V1 | C24: =C14/B14 -> 0.41176471
A26: Test (one-sided, V1 slower) | B26: Value | D26: Note
A27: Welch t on ln(t): t | B27: =(B18-C18)/SQRT(B19^2/B13+C19^2/C13) -> 1.8946193
A28: Welch df | B28: =(B19^2/B13+C19^2/C13)^2/((B19^2/B13)^2/(B13-1)+(C19^2/C13)^2/(C13-1)) -> 79.876076
A29: Welch t on ln(t): p | B29: =TDIST(ABS(B27),B28,1) -> 0.030900979 | D29: Excel truncates df to an integer; scipy gives 0.031
A30: Permutation test, median: p | B30: 0.016 | D30: results/report/reacquire_table.md
A31: Permutation test, mean: p | B31: 0.032 | D31: results/report/reacquire_table.md
A32: Mann-Whitney U: p | B32: 0.067 | D32: scipy.stats.mannwhitneyu (make_graphs.py)
A33: Shapiro-Wilk on ln(t), V1: p | B33: 0.0026 | D33: < 0.05: log-normal is approximate
A34: Shapiro-Wilk on ln(t), V2: p | B34: 0.0006 | D34: < 0.05: log-normal is approximate
A36: Source: raw_reacquire (data/raw/reacquire_losses.csv), hardware, three boxes. Black formula cells recalculate; typed numbers (CI, permutation, Mann-Whitney, Shapiro) come from make_graphs.py / reacquire_report.py.

Sheet 09 Reliability
A1: t_s | B1: V1_reacquired_pct | C1: V2_reacquired_pct | D1: V1_lognormal_fit_pct | E1: V2_lognormal_fit_pct | G1: Within_s | H1: V1_back | I1: V1_pct | J1: V1_CI_low | K1: V1_CI_high | L1: V2_back | M1: V2_pct | N1: V2_CI_low | O1: V2_CI_high
A2: 0 | B2: =100*COUNTIFS(raw_reacquire!$B$2:$B$71,"<="&A2)/'08 Latency dist'!$B$13 -> 0 | C2: =100*COUNTIFS(raw_reacquire!$B$72:$B$108,"<="&A2)/'08 Latency dist'!$C$13 -> 0 | D2: =IF(A2<=0,0,100*NORMDIST(LN(A2),'08 Latency dist'!$B$18,'08 Latency dist'!$B$19,TRUE())) -> 0 | E2: =IF(A2<=0,0,100*NORMDIST(LN(A2),'08 Latency dist'!$C$18,'08 Latency dist'!$C$19,TRUE())) -> 0 | G2: 0.5 | H2: =COUNTIFS(raw_reacquire!$B$2:$B$71,"<="&G2) -> 33 | I2: =100*H2/'08 Latency dist'!$B$13 -> 47.142857 | J2: =100*(((H2/'08 Latency dist'!$B$13)+1.96^2/(2*'08 Latency dist'!$B$13))/(1+1.96^2/'08 Latency dist'!$B$13)-1.96*SQRT((H2/'08 Latency dist'!$B$13)*(1-(H2/'08 Latency dist'!$B$13))/'08 Latency dist'!$B$13+1.96^2/(4*'08 Latency dist'!$B$13^2))/(1+1.96^2/'08 Latency dist'!$B$13)) -> 35.904683 | K2: =100*(((H2/'08 Latency dist'!$B$13)+1.96^2/(2*'08 Latency dist'!$B$13))/(1+1.96^2/'08 Latency dist'!$B$13)+1.96*SQRT((H2/'08 Latency dist'!$B$13)*(1-(H2/'08 Latency dist'!$B$13))/'08 Latency dist'!$B$13+1.96^2/(4*'08 Latency dist'!$B$13^2))/(1+1.96^2/'08 Latency dist'!$B$13)) -> 58.678316 | L2: =COUNTIFS(raw_reacquire!$B$72:$B$108,"<="&G2) -> 26 | M2: =100*L2/'08 Latency dist'!$C$13 -> 70.27027 | N2: =100*(((L2/'08 Latency dist'!$C$13)+1.96^2/(2*'08 Latency dist'!$C$13))/(1+1.96^2/'08 Latency dist'!$C$13)-1.96*SQRT((L2/'08 Latency dist'!$C$13)*(1-(L2/'08 Latency dist'!$C$13))/'08 Latency dist'!$C$13+1.96^2/(4*'08 Latency dist'!$C$13^2))/(1+1.96^2/'08 Latency dist'!$C$13)) -> 54.216561 | O2: =100*(((L2/'08 Latency dist'!$C$13)+1.96^2/(2*'08 Latency dist'!$C$13))/(1+1.96^2/'08 Latency dist'!$C$13)+1.96*SQRT((L2/'08 Latency dist'!$C$13)*(1-(L2/'08 Latency dist'!$C$13))/'08 Latency dist'!$C$13+1.96^2/(4*'08 Latency dist'!$C$13^2))/(1+1.96^2/'08 Latency dist'!$C$13)) -> 82.510698
A3: 0.1 | B3: =100*COUNTIFS(raw_reacquire!$B$2:$B$71,"<="&A3)/'08 Latency dist'!$B$13 -> 21.428571 | C3: =100*COUNTIFS(raw_reacquire!$B$72:$B$108,"<="&A3)/'08 Latency dist'!$C$13 -> 35.135135 | D3: =IF(A3<=0,0,100*NORMDIST(LN(A3),'08 Latency dist'!$B$18,'08 Latency dist'!$B$19,TRUE())) -> 9.0685455 | E3: =IF(A3<=0,0,100*NORMDIST(LN(A3),'08 Latency dist'!$C$18,'08 Latency dist'!$C$19,TRUE())) -> 14.147389 | G3: 1 | H3: =COUNTIFS(raw_reacquire!$B$2:$B$71,"<="&G3) -> 56 | I3: =100*H3/'08 Latency dist'!$B$13 -> 80 | J3: =100*(((H3/'08 Latency dist'!$B$13)+1.96^2/(2*'08 Latency dist'!$B$13))/(1+1.96^2/'08 Latency dist'!$B$13)-1.96*SQRT((H3/'08 Latency dist'!$B$13)*(1-(H3/'08 Latency dist'!$B$13))/'08 Latency dist'!$B$13+1.96^2/(4*'08 Latency dist'!$B$13^2))/(1+1.96^2/'08 Latency dist'!$B$13)) -> 69.183135 | K3: =100*(((H3/'08 Latency dist'!$B$13)+1.96^2/(2*'08 Latency dist'!$B$13))/(1+1.96^2/'08 Latency dist'!$B$13)+1.96*SQRT((H3/'08 Latency dist'!$B$13)*(1-(H3/'08 Latency dist'!$B$13))/'08 Latency dist'!$B$13+1.96^2/(4*'08 Latency dist'!$B$13^2))/(1+1.96^2/'08 Latency dist'!$B$13)) -> 87.695372 | L3: =COUNTIFS(raw_reacquire!$B$72:$B$108,"<="&G3) -> 31 | M3: =100*L3/'08 Latency dist'!$C$13 -> 83.783784 | N3: =100*(((L3/'08 Latency dist'!$C$13)+1.96^2/(2*'08 Latency dist'!$C$13))/(1+1.96^2/'08 Latency dist'!$C$13)-1.96*SQRT((L3/'08 Latency dist'!$C$13)*(1-(L3/'08 Latency dist'!$C$13))/'08 Latency dist'!$C$13+1.96^2/(4*'08 Latency dist'!$C$13^2))/(1+1.96^2/'08 Latency dist'!$C$13)) -> 68.863201 | O3: =100*(((L3/'08 Latency dist'!$C$13)+1.96^2/(2*'08 Latency dist'!$C$13))/(1+1.96^2/'08 Latency dist'!$C$13)+1.96*SQRT((L3/'08 Latency dist'!$C$13)*(1-(L3/'08 Latency dist'!$C$13))/'08 Latency dist'!$C$13+1.96^2/(4*'08 Latency dist'!$C$13^2))/(1+1.96^2/'08 Latency dist'!$C$13)) -> 92.348897
A4: 0.2 | B4: =100*COUNTIFS(raw_reacquire!$B$2:$B$71,"<="&A4)/'08 Latency dist'!$B$13 -> 30 | C4: =100*COUNTIFS(raw_reacquire!$B$72:$B$108,"<="&A4)/'08 Latency dist'!$C$13 -> 37.837838 | D4: =IF(A4<=0,0,100*NORMDIST(LN(A4),'08 Latency dist'!$B$18,'08 Latency dist'!$B$19,TRUE())) -> 24.172394 | E4: =IF(A4<=0,0,100*NORMDIST(LN(A4),'08 Latency dist'!$C$18,'08 Latency dist'!$C$19,TRUE())) -> 35.453128 | G4: 2 | H4: =COUNTIFS(raw_reacquire!$B$2:$B$71,"<="&G4) -> 63 | I4: =100*H4/'08 Latency dist'!$B$13 -> 90 | J4: =100*(((H4/'08 Latency dist'!$B$13)+1.96^2/(2*'08 Latency dist'!$B$13))/(1+1.96^2/'08 Latency dist'!$B$13)-1.96*SQRT((H4/'08 Latency dist'!$B$13)*(1-(H4/'08 Latency dist'!$B$13))/'08 Latency dist'!$B$13+1.96^2/(4*'08 Latency dist'!$B$13^2))/(1+1.96^2/'08 Latency dist'!$B$13)) -> 80.766878 | K4: =100*(((H4/'08 Latency dist'!$B$13)+1.96^2/(2*'08 Latency dist'!$B$13))/(1+1.96^2/'08 Latency dist'!$B$13)+1.96*SQRT((H4/'08 Latency dist'!$B$13)*(1-(H4/'08 Latency dist'!$B$13))/'08 Latency dist'!$B$13+1.96^2/(4*'08 Latency dist'!$B$13^2))/(1+1.96^2/'08 Latency dist'!$B$13)) -> 95.071132 | L4: =COUNTIFS(raw_reacquire!$B$72:$B$108,"<="&G4) -> 36 | M4: =100*L4/'08 Latency dist'!$C$13 -> 97.297297 | N4: =100*(((L4/'08 Latency dist'!$C$13)+1.96^2/(2*'08 Latency dist'!$C$13))/(1+1.96^2/'08 Latency dist'!$C$13)-1.96*SQRT((L4/'08 Latency dist'!$C$13)*(1-(L4/'08 Latency dist'!$C$13))/'08 Latency dist'!$C$13+1.96^2/(4*'08 Latency dist'!$C$13^2))/(1+1.96^2/'08 Latency dist'!$C$13)) -> 86.175622 | O4: =100*(((L4/'08 Latency dist'!$C$13)+1.96^2/(2*'08 Latency dist'!$C$13))/(1+1.96^2/'08 Latency dist'!$C$13)+1.96*SQRT((L4/'08 Latency dist'!$C$13)*(1-(L4/'08 Latency dist'!$C$13))/'08 Latency dist'!$C$13+1.96^2/(4*'08 Latency dist'!$C$13^2))/(1+1.96^2/'08 Latency dist'!$C$13)) -> 99.521315
A5: 0.3 | B5: =100*COUNTIFS(raw_reacquire!$B$2:$B$71,"<="&A5)/'08 Latency dist'!$B$13 -> 38.571429 | C5: =100*COUNTIFS(raw_reacquire!$B$72:$B$108,"<="&A5)/'08 Latency dist'!$C$13 -> 51.351351 | D5: =IF(A5<=0,0,100*NORMDIST(LN(A5),'08 Latency dist'!$B$18,'08 Latency dist'!$B$19,TRUE())) -> 37.113015 | E5: =IF(A5<=0,0,100*NORMDIST(LN(A5),'08 Latency dist'!$C$18,'08 Latency dist'!$C$19,TRUE())) -> 51.46429 | G5: 3 | H5: =COUNTIFS(raw_reacquire!$B$2:$B$71,"<="&G5) -> 67 | I5: =100*H5/'08 Latency dist'!$B$13 -> 95.714286 | J5: =100*(((H5/'08 Latency dist'!$B$13)+1.96^2/(2*'08 Latency dist'!$B$13))/(1+1.96^2/'08 Latency dist'!$B$13)-1.96*SQRT((H5/'08 Latency dist'!$B$13)*(1-(H5/'08 Latency dist'!$B$13))/'08 Latency dist'!$B$13+1.96^2/(4*'08 Latency dist'!$B$13^2))/(1+1.96^2/'08 Latency dist'!$B$13)) -> 88.140139 | K5: =100*(((H5/'08 Latency dist'!$B$13)+1.96^2/(2*'08 Latency dist'!$B$13))/(1+1.96^2/'08 Latency dist'!$B$13)+1.96*SQRT((H5/'08 Latency dist'!$B$13)*(1-(H5/'08 Latency dist'!$B$13))/'08 Latency dist'!$B$13+1.96^2/(4*'08 Latency dist'!$B$13^2))/(1+1.96^2/'08 Latency dist'!$B$13)) -> 98.531873 | L5: =COUNTIFS(raw_reacquire!$B$72:$B$108,"<="&G5) -> 37 | M5: =100*L5/'08 Latency dist'!$C$13 -> 100 | N5: =100*(((L5/'08 Latency dist'!$C$13)+1.96^2/(2*'08 Latency dist'!$C$13))/(1+1.96^2/'08 Latency dist'!$C$13)-1.96*SQRT((L5/'08 Latency dist'!$C$13)*(1-(L5/'08 Latency dist'!$C$13))/'08 Latency dist'!$C$13+1.96^2/(4*'08 Latency dist'!$C$13^2))/(1+1.96^2/'08 Latency dist'!$C$13)) -> 90.593904 | O5: =100*(((L5/'08 Latency dist'!$C$13)+1.96^2/(2*'08 Latency dist'!$C$13))/(1+1.96^2/'08 Latency dist'!$C$13)+1.96*SQRT((L5/'08 Latency dist'!$C$13)*(1-(L5/'08 Latency dist'!$C$13))/'08 Latency dist'!$C$13+1.96^2/(4*'08 Latency dist'!$C$13^2))/(1+1.96^2/'08 Latency dist'!$C$13)) -> 100
A6: 0.4 | B6: =100*COUNTIFS(raw_reacquire!$B$2:$B$71,"<="&A6)/'08 Latency dist'!$B$13 -> 45.714286 | C6: =100*COUNTIFS(raw_reacquire!$B$72:$B$108,"<="&A6)/'08 Latency dist'!$C$13 -> 62.162162 | D6: =IF(A6<=0,0,100*NORMDIST(LN(A6),'08 Latency dist'!$B$18,'08 Latency dist'!$B$19,TRUE())) -> 47.409103 | E6: =IF(A6<=0,0,100*NORMDIST(LN(A6),'08 Latency dist'!$C$18,'08 Latency dist'!$C$19,TRUE())) -> 62.835139 | G6: CI = 95 % Wilson score interval.
A7: 0.5 | B7: =100*COUNTIFS(raw_reacquire!$B$2:$B$71,"<="&A7)/'08 Latency dist'!$B$13 -> 47.142857 | C7: =100*COUNTIFS(raw_reacquire!$B$72:$B$108,"<="&A7)/'08 Latency dist'!$C$13 -> 70.27027 | D7: =IF(A7<=0,0,100*NORMDIST(LN(A7),'08 Latency dist'!$B$18,'08 Latency dist'!$B$19,TRUE())) -> 55.554553 | E7: =IF(A7<=0,0,100*NORMDIST(LN(A7),'08 Latency dist'!$C$18,'08 Latency dist'!$C$19,TRUE())) -> 70.988018
A8: 0.6 | B8: =100*COUNTIFS(raw_reacquire!$B$2:$B$71,"<="&A8)/'08 Latency dist'!$B$13 -> 57.142857 | C8: =100*COUNTIFS(raw_reacquire!$B$72:$B$108,"<="&A8)/'08 Latency dist'!$C$13 -> 70.27027 | D8: =IF(A8<=0,0,100*NORMDIST(LN(A8),'08 Latency dist'!$B$18,'08 Latency dist'!$B$19,TRUE())) -> 62.05465 | E8: =IF(A8<=0,0,100*NORMDIST(LN(A8),'08 Latency dist'!$C$18,'08 Latency dist'!$C$19,TRUE())) -> 76.953553 | G8: Loss rate | H8: V1 | I8: V2 | J8: Note
A9: 0.7 | B9: =100*COUNTIFS(raw_reacquire!$B$2:$B$71,"<="&A9)/'08 Latency dist'!$B$13 -> 65.714286 | C9: =100*COUNTIFS(raw_reacquire!$B$72:$B$108,"<="&A9)/'08 Latency dist'!$C$13 -> 70.27027 | D9: =IF(A9<=0,0,100*NORMDIST(LN(A9),'08 Latency dist'!$B$18,'08 Latency dist'!$B$19,TRUE())) -> 67.303476 | E9: =IF(A9<=0,0,100*NORMDIST(LN(A9),'08 Latency dist'!$C$18,'08 Latency dist'!$C$19,TRUE())) -> 81.410553 | G9: Losses (n) | H9: ='08 Latency dist'!B13 -> 70 | I9: ='08 Latency dist'!C13 -> 37
A10: 0.8 | B10: =100*COUNTIFS(raw_reacquire!$B$2:$B$71,"<="&A10)/'08 Latency dist'!$B$13 -> 71.428571 | C10: =100*COUNTIFS(raw_reacquire!$B$72:$B$108,"<="&A10)/'08 Latency dist'!$C$13 -> 72.972973 | D10: =IF(A10<=0,0,100*NORMDIST(LN(A10),'08 Latency dist'!$B$18,'08 Latency dist'!$B$19,TRUE())) -> 71.592836 | E10: =IF(A10<=0,0,100*NORMDIST(LN(A10),'08 Latency dist'!$C$18,'08 Latency dist'!$C$19,TRUE())) -> 84.804758 | G10: Tracking time (s) | H10: 305 | I10: 112 | J10: results/report/reacquire_table.md
A11: 0.9 | B11: =100*COUNTIFS(raw_reacquire!$B$2:$B$71,"<="&A11)/'08 Latency dist'!$B$13 -> 77.142857 | C11: =100*COUNTIFS(raw_reacquire!$B$72:$B$108,"<="&A11)/'08 Latency dist'!$C$13 -> 78.378378 | D11: =IF(A11<=0,0,100*NORMDIST(LN(A11),'08 Latency dist'!$B$18,'08 Latency dist'!$B$19,TRUE())) -> 75.137489 | E11: =IF(A11<=0,0,100*NORMDIST(LN(A11),'08 Latency dist'!$C$18,'08 Latency dist'!$C$19,TRUE())) -> 87.433936 | G11: Losses per tracking min | H11: =H9/H10*60 -> 13.770492 | I11: =I9/I10*60 -> 19.821429
A12: 1 | B12: =100*COUNTIFS(raw_reacquire!$B$2:$B$71,"<="&A12)/'08 Latency dist'!$B$13 -> 80 | C12: =100*COUNTIFS(raw_reacquire!$B$72:$B$108,"<="&A12)/'08 Latency dist'!$C$13 -> 83.783784 | D12: =IF(A12<=0,0,100*NORMDIST(LN(A12),'08 Latency dist'!$B$18,'08 Latency dist'!$B$19,TRUE())) -> 78.096692 | E12: =IF(A12<=0,0,100*NORMDIST(LN(A12),'08 Latency dist'!$C$18,'08 Latency dist'!$C$19,TRUE())) -> 89.50136 | G12: 95% CI low | H12: =CHIINV(0.975,2*H9)/2/H10*60 -> 10.734774 | I12: =CHIINV(0.975,2*I9)/2/I10*60 -> 13.956115 | J12: Exact Poisson interval
A13: 1.1 | B13: =100*COUNTIFS(raw_reacquire!$B$2:$B$71,"<="&A13)/'08 Latency dist'!$B$13 -> 84.285714 | C13: =100*COUNTIFS(raw_reacquire!$B$72:$B$108,"<="&A13)/'08 Latency dist'!$C$13 -> 89.189189 | D13: =IF(A13<=0,0,100*NORMDIST(LN(A13),'08 Latency dist'!$B$18,'08 Latency dist'!$B$19,TRUE())) -> 80.589955 | E13: =IF(A13<=0,0,100*NORMDIST(LN(A13),'08 Latency dist'!$C$18,'08 Latency dist'!$C$19,TRUE())) -> 91.148815 | G13: 95% CI high | H13: =CHIINV(0.025,2*H9+2)/2/H10*60 -> 17.398188 | I13: =CHIINV(0.025,2*I9+2)/2/I10*60 -> 27.321228
A14: 1.2 | B14: =100*COUNTIFS(raw_reacquire!$B$2:$B$71,"<="&A14)/'08 Latency dist'!$B$13 -> 84.285714 | C14: =100*COUNTIFS(raw_reacquire!$B$72:$B$108,"<="&A14)/'08 Latency dist'!$C$13 -> 94.594595 | D14: =IF(A14<=0,0,100*NORMDIST(LN(A14),'08 Latency dist'!$B$18,'08 Latency dist'!$B$19,TRUE())) -> 82.708138 | E14: =IF(A14<=0,0,100*NORMDIST(LN(A14),'08 Latency dist'!$C$18,'08 Latency dist'!$C$19,TRUE())) -> 92.477213 | G14: Poisson rate test p | I14: 0.099 | J14: scipy poisson_means_test, two-sided: V2 rate not significantly different
A15: 1.3 | B15: =100*COUNTIFS(raw_reacquire!$B$2:$B$71,"<="&A15)/'08 Latency dist'!$B$13 -> 84.285714 | C15: =100*COUNTIFS(raw_reacquire!$B$72:$B$108,"<="&A15)/'08 Latency dist'!$C$13 -> 94.594595 | D15: =IF(A15<=0,0,100*NORMDIST(LN(A15),'08 Latency dist'!$B$18,'08 Latency dist'!$B$19,TRUE())) -> 84.521204 | E15: =IF(A15<=0,0,100*NORMDIST(LN(A15),'08 Latency dist'!$C$18,'08 Latency dist'!$C$19,TRUE())) -> 93.559705 | G15: Fix from 2+ boxes (%) | H15: 70 | I15: 67 | J15: results/report/reacquire_table.md
A16: 1.4 | B16: =100*COUNTIFS(raw_reacquire!$B$2:$B$71,"<="&A16)/'08 Latency dist'!$B$13 -> 84.285714 | C16: =100*COUNTIFS(raw_reacquire!$B$72:$B$108,"<="&A16)/'08 Latency dist'!$C$13 -> 97.297297 | D16: =IF(A16<=0,0,100*NORMDIST(LN(A16),'08 Latency dist'!$B$18,'08 Latency dist'!$B$19,TRUE())) -> 86.08368 | E16: =IF(A16<=0,0,100*NORMDIST(LN(A16),'08 Latency dist'!$C$18,'08 Latency dist'!$C$19,TRUE())) -> 94.450207
A17: 1.5 | B17: =100*COUNTIFS(raw_reacquire!$B$2:$B$71,"<="&A17)/'08 Latency dist'!$B$13 -> 84.285714 | C17: =100*COUNTIFS(raw_reacquire!$B$72:$B$108,"<="&A17)/'08 Latency dist'!$C$13 -> 97.297297 | D17: =IF(A17<=0,0,100*NORMDIST(LN(A17),'08 Latency dist'!$B$18,'08 Latency dist'!$B$19,TRUE())) -> 87.438547 | E17: =IF(A17<=0,0,100*NORMDIST(LN(A17),'08 Latency dist'!$C$18,'08 Latency dist'!$C$19,TRUE())) -> 95.189062
A18: 1.6 | B18: =100*COUNTIFS(raw_reacquire!$B$2:$B$71,"<="&A18)/'08 Latency dist'!$B$13 -> 85.714286 | C18: =100*COUNTIFS(raw_reacquire!$B$72:$B$108,"<="&A18)/'08 Latency dist'!$C$13 -> 97.297297 | D18: =IF(A18<=0,0,100*NORMDIST(LN(A18),'08 Latency dist'!$B$18,'08 Latency dist'!$B$19,TRUE())) -> 88.620036 | E18: =IF(A18<=0,0,100*NORMDIST(LN(A18),'08 Latency dist'!$C$18,'08 Latency dist'!$C$19,TRUE())) -> 95.80687
A19: 1.7 | B19: =100*COUNTIFS(raw_reacquire!$B$2:$B$71,"<="&A19)/'08 Latency dist'!$B$13 -> 87.142857 | C19: =100*COUNTIFS(raw_reacquire!$B$72:$B$108,"<="&A19)/'08 Latency dist'!$C$13 -> 97.297297 | D19: =IF(A19<=0,0,100*NORMDIST(LN(A19),'08 Latency dist'!$B$18,'08 Latency dist'!$B$19,TRUE())) -> 89.655674 | E19: =IF(A19<=0,0,100*NORMDIST(LN(A19),'08 Latency dist'!$C$18,'08 Latency dist'!$C$19,TRUE())) -> 96.327128
A20: 1.8 | B20: =100*COUNTIFS(raw_reacquire!$B$2:$B$71,"<="&A20)/'08 Latency dist'!$B$13 -> 88.571429 | C20: =100*COUNTIFS(raw_reacquire!$B$72:$B$108,"<="&A20)/'08 Latency dist'!$C$13 -> 97.297297 | D20: =IF(A20<=0,0,100*NORMDIST(LN(A20),'08 Latency dist'!$B$18,'08 Latency dist'!$B$19,TRUE())) -> 90.567793 | E20: =IF(A20<=0,0,100*NORMDIST(LN(A20),'08 Latency dist'!$C$18,'08 Latency dist'!$C$19,TRUE())) -> 96.768085
A21: 1.9 | B21: =100*COUNTIFS(raw_reacquire!$B$2:$B$71,"<="&A21)/'08 Latency dist'!$B$13 -> 90 | C21: =100*COUNTIFS(raw_reacquire!$B$72:$B$108,"<="&A21)/'08 Latency dist'!$C$13 -> 97.297297 | D21: =IF(A21<=0,0,100*NORMDIST(LN(A21),'08 Latency dist'!$B$18,'08 Latency dist'!$B$19,TRUE())) -> 91.374658 | E21: =IF(A21<=0,0,100*NORMDIST(LN(A21),'08 Latency dist'!$C$18,'08 Latency dist'!$C$19,TRUE())) -> 97.144059
A22: 2 | B22: =100*COUNTIFS(raw_reacquire!$B$2:$B$71,"<="&A22)/'08 Latency dist'!$B$13 -> 90 | C22: =100*COUNTIFS(raw_reacquire!$B$72:$B$108,"<="&A22)/'08 Latency dist'!$C$13 -> 97.297297 | D22: =IF(A22<=0,0,100*NORMDIST(LN(A22),'08 Latency dist'!$B$18,'08 Latency dist'!$B$19,TRUE())) -> 92.091321 | E22: =IF(A22<=0,0,100*NORMDIST(LN(A22),'08 Latency dist'!$C$18,'08 Latency dist'!$C$19,TRUE())) -> 97.466392
A23: 2.1 | B23: =100*COUNTIFS(raw_reacquire!$B$2:$B$71,"<="&A23)/'08 Latency dist'!$B$13 -> 90 | C23: =100*COUNTIFS(raw_reacquire!$B$72:$B$108,"<="&A23)/'08 Latency dist'!$C$13 -> 97.297297 | D23: =IF(A23<=0,0,100*NORMDIST(LN(A23),'08 Latency dist'!$B$18,'08 Latency dist'!$B$19,TRUE())) -> 92.730271 | E23: =IF(A23<=0,0,100*NORMDIST(LN(A23),'08 Latency dist'!$C$18,'08 Latency dist'!$C$19,TRUE())) -> 97.744144
A24: 2.2 | B24: =100*COUNTIFS(raw_reacquire!$B$2:$B$71,"<="&A24)/'08 Latency dist'!$B$13 -> 90 | C24: =100*COUNTIFS(raw_reacquire!$B$72:$B$108,"<="&A24)/'08 Latency dist'!$C$13 -> 97.297297 | D24: =IF(A24<=0,0,100*NORMDIST(LN(A24),'08 Latency dist'!$B$18,'08 Latency dist'!$B$19,TRUE())) -> 93.301941 | E24: =IF(A24<=0,0,100*NORMDIST(LN(A24),'08 Latency dist'!$C$18,'08 Latency dist'!$C$19,TRUE())) -> 97.984614
A25: 2.3 | B25: =100*COUNTIFS(raw_reacquire!$B$2:$B$71,"<="&A25)/'08 Latency dist'!$B$13 -> 91.428571 | C25: =100*COUNTIFS(raw_reacquire!$B$72:$B$108,"<="&A25)/'08 Latency dist'!$C$13 -> 97.297297 | D25: =IF(A25<=0,0,100*NORMDIST(LN(A25),'08 Latency dist'!$B$18,'08 Latency dist'!$B$19,TRUE())) -> 93.815097 | E25: =IF(A25<=0,0,100*NORMDIST(LN(A25),'08 Latency dist'!$C$18,'08 Latency dist'!$C$19,TRUE())) -> 98.193723
A26: 2.4 | B26: =100*COUNTIFS(raw_reacquire!$B$2:$B$71,"<="&A26)/'08 Latency dist'!$B$13 -> 94.285714 | C26: =100*COUNTIFS(raw_reacquire!$B$72:$B$108,"<="&A26)/'08 Latency dist'!$C$13 -> 97.297297 | D26: =IF(A26<=0,0,100*NORMDIST(LN(A26),'08 Latency dist'!$B$18,'08 Latency dist'!$B$19,TRUE())) -> 94.277144 | E26: =IF(A26<=0,0,100*NORMDIST(LN(A26),'08 Latency dist'!$C$18,'08 Latency dist'!$C$19,TRUE())) -> 98.376309
A27: 2.5 | B27: =100*COUNTIFS(raw_reacquire!$B$2:$B$71,"<="&A27)/'08 Latency dist'!$B$13 -> 94.285714 | C27: =100*COUNTIFS(raw_reacquire!$B$72:$B$108,"<="&A27)/'08 Latency dist'!$C$13 -> 100 | D27: =IF(A27<=0,0,100*NORMDIST(LN(A27),'08 Latency dist'!$B$18,'08 Latency dist'!$B$19,TRUE())) -> 94.694373 | E27: =IF(A27<=0,0,100*NORMDIST(LN(A27),'08 Latency dist'!$C$18,'08 Latency dist'!$C$19,TRUE())) -> 98.53635
... A67: 6.5 | B67: =100*COUNTIFS(raw_reacquire!$B$2:$B$71,"<="&A67)/'08 Latency dist'!$B$13 -> 100 | C67: =100*COUNTIFS(raw_reacquire!$B$72:$B$108,"<="&A67)/'08 Latency dist'!$C$13 -> 100 | D67: =IF(A67<=0,0,100*NORMDIST(LN(A67),'08 Latency dist'!$B$18,'08 Latency dist'!$B$19,TRUE())) -> 99.365483 | E67: =IF(A67<=0,0,100*NORMDIST(LN(A67),'08 Latency dist'!$C$18,'08 Latency dist'!$C$19,TRUE())) -> 99.917122
A69: Share of losses already reacquired t seconds after the loss (empirical CDF) and the fitted log-normal CDF. Source: raw_reacquire; fit parameters from sheet 08.

Sheet 10 Stand dist
A1: Losses_per_min | B1: Before_trials | C1: After_trials | D1: Before_normal_fit | E1: After_normal_fit
A2: 0 | B2: =COUNTIFS(raw_stand_bench!$E$2:$E$46,">="&A2-1,raw_stand_bench!$E$2:$E$46,"<"&A2+1) -> 1 | C2: =COUNTIFS(raw_stand_bench!$E$47:$E$91,">="&A2-1,raw_stand_bench!$E$47:$E$91,"<"&A2+1) -> 27 | D2: =$B$24*(NORMDIST(A2+1,$B$25,$B$26,TRUE())-NORMDIST(A2-1,$B$25,$B$26,TRUE())) -> 0.84280878 | E2: =$C$24*(NORMDIST(A2+1,$C$25,$C$26,TRUE())-NORMDIST(A2-1,$C$25,$C$26,TRUE())) -> 16.361436
A3: 2 | B3: =COUNTIFS(raw_stand_bench!$E$2:$E$46,">="&A3-1,raw_stand_bench!$E$2:$E$46,"<"&A3+1) -> 2 | C3: =COUNTIFS(raw_stand_bench!$E$47:$E$91,">="&A3-1,raw_stand_bench!$E$47:$E$91,"<"&A3+1) -> 12 | D3: =$B$24*(NORMDIST(A3+1,$B$25,$B$26,TRUE())-NORMDIST(A3-1,$B$25,$B$26,TRUE())) -> 1.4865372 | E3: =$C$24*(NORMDIST(A3+1,$C$25,$C$26,TRUE())-NORMDIST(A3-1,$C$25,$C$26,TRUE())) -> 18.047909
A4: 4 | B4: =COUNTIFS(raw_stand_bench!$E$2:$E$46,">="&A4-1,raw_stand_bench!$E$2:$E$46,"<"&A4+1) -> 0 | C4: =COUNTIFS(raw_stand_bench!$E$47:$E$91,">="&A4-1,raw_stand_bench!$E$47:$E$91,"<"&A4+1) -> 4 | D4: =$B$24*(NORMDIST(A4+1,$B$25,$B$26,TRUE())-NORMDIST(A4-1,$B$25,$B$26,TRUE())) -> 2.372543 | E4: =$C$24*(NORMDIST(A4+1,$C$25,$C$26,TRUE())-NORMDIST(A4-1,$C$25,$C$26,TRUE())) -> 5.6194944
A5: 6 | B5: =COUNTIFS(raw_stand_bench!$E$2:$E$46,">="&A5-1,raw_stand_bench!$E$2:$E$46,"<"&A5+1) -> 7 | C5: =COUNTIFS(raw_stand_bench!$E$47:$E$91,">="&A5-1,raw_stand_bench!$E$47:$E$91,"<"&A5+1) -> 2 | D5: =$B$24*(NORMDIST(A5+1,$B$25,$B$26,TRUE())-NORMDIST(A5-1,$B$25,$B$26,TRUE())) -> 3.4264599 | E5: =$C$24*(NORMDIST(A5+1,$C$25,$C$26,TRUE())-NORMDIST(A5-1,$C$25,$C$26,TRUE())) -> 0.4831469
A6: 8 | B6: =COUNTIFS(raw_stand_bench!$E$2:$E$46,">="&A6-1,raw_stand_bench!$E$2:$E$46,"<"&A6+1) -> 9 | C6: =COUNTIFS(raw_stand_bench!$E$47:$E$91,">="&A6-1,raw_stand_bench!$E$47:$E$91,"<"&A6+1) -> 0 | D6: =$B$24*(NORMDIST(A6+1,$B$25,$B$26,TRUE())-NORMDIST(A6-1,$B$25,$B$26,TRUE())) -> 4.4778735 | E6: =$C$24*(NORMDIST(A6+1,$C$25,$C$26,TRUE())-NORMDIST(A6-1,$C$25,$C$26,TRUE())) -> 0.011102881
A7: 10 | B7: =COUNTIFS(raw_stand_bench!$E$2:$E$46,">="&A7-1,raw_stand_bench!$E$2:$E$46,"<"&A7+1) -> 1 | C7: =COUNTIFS(raw_stand_bench!$E$47:$E$91,">="&A7-1,raw_stand_bench!$E$47:$E$91,"<"&A7+1) -> 0 | D7: =$B$24*(NORMDIST(A7+1,$B$25,$B$26,TRUE())-NORMDIST(A7-1,$B$25,$B$26,TRUE())) -> 5.2953367 | E7: =$C$24*(NORMDIST(A7+1,$C$25,$C$26,TRUE())-NORMDIST(A7-1,$C$25,$C$26,TRUE())) -> 6.6206731e-05
A8: 12 | B8: =COUNTIFS(raw_stand_bench!$E$2:$E$46,">="&A8-1,raw_stand_bench!$E$2:$E$46,"<"&A8+1) -> 3 | C8: =COUNTIFS(raw_stand_bench!$E$47:$E$91,">="&A8-1,raw_stand_bench!$E$47:$E$91,"<"&A8+1) -> 0 | D8: =$B$24*(NORMDIST(A8+1,$B$25,$B$26,TRUE())-NORMDIST(A8-1,$B$25,$B$26,TRUE())) -> 5.6664562 | E8: =$C$24*(NORMDIST(A8+1,$C$25,$C$26,TRUE())-NORMDIST(A8-1,$C$25,$C$26,TRUE())) -> 1.0024318e-07
A9: 14 | B9: =COUNTIFS(raw_stand_bench!$E$2:$E$46,">="&A9-1,raw_stand_bench!$E$2:$E$46,"<"&A9+1) -> 6 | C9: =COUNTIFS(raw_stand_bench!$E$47:$E$91,">="&A9-1,raw_stand_bench!$E$47:$E$91,"<"&A9+1) -> 0 | D9: =$B$24*(NORMDIST(A9+1,$B$25,$B$26,TRUE())-NORMDIST(A9-1,$B$25,$B$26,TRUE())) -> 5.4868863 | E9: =$C$24*(NORMDIST(A9+1,$C$25,$C$26,TRUE())-NORMDIST(A9-1,$C$25,$C$26,TRUE())) -> 3.7984615e-11
A10: 16 | B10: =COUNTIFS(raw_stand_bench!$E$2:$E$46,">="&A10-1,raw_stand_bench!$E$2:$E$46,"<"&A10+1) -> 5 | C10: =COUNTIFS(raw_stand_bench!$E$47:$E$91,">="&A10-1,raw_stand_bench!$E$47:$E$91,"<"&A10+1) -> 0 | D10: =$B$24*(NORMDIST(A10+1,$B$25,$B$26,TRUE())-NORMDIST(A10-1,$B$25,$B$26,TRUE())) -> 4.8076929 | E10: =$C$24*(NORMDIST(A10+1,$C$25,$C$26,TRUE())-NORMDIST(A10-1,$C$25,$C$26,TRUE())) -> 0
A11: 18 | B11: =COUNTIFS(raw_stand_bench!$E$2:$E$46,">="&A11-1,raw_stand_bench!$E$2:$E$46,"<"&A11+1) -> 3 | C11: =COUNTIFS(raw_stand_bench!$E$47:$E$91,">="&A11-1,raw_stand_bench!$E$47:$E$91,"<"&A11+1) -> 0 | D11: =$B$24*(NORMDIST(A11+1,$B$25,$B$26,TRUE())-NORMDIST(A11-1,$B$25,$B$26,TRUE())) -> 3.811916 | E11: =$C$24*(NORMDIST(A11+1,$C$25,$C$26,TRUE())-NORMDIST(A11-1,$C$25,$C$26,TRUE())) -> 0
A12: 20 | B12: =COUNTIFS(raw_stand_bench!$E$2:$E$46,">="&A12-1,raw_stand_bench!$E$2:$E$46,"<"&A12+1) -> 4 | C12: =COUNTIFS(raw_stand_bench!$E$47:$E$91,">="&A12-1,raw_stand_bench!$E$47:$E$91,"<"&A12+1) -> 0 | D12: =$B$24*(NORMDIST(A12+1,$B$25,$B$26,TRUE())-NORMDIST(A12-1,$B$25,$B$26,TRUE())) -> 2.7349219 | E12: =$C$24*(NORMDIST(A12+1,$C$25,$C$26,TRUE())-NORMDIST(A12-1,$C$25,$C$26,TRUE())) -> 0
A13: 22 | B13: =COUNTIFS(raw_stand_bench!$E$2:$E$46,">="&A13-1,raw_stand_bench!$E$2:$E$46,"<"&A13+1) -> 2 | C13: =COUNTIFS(raw_stand_bench!$E$47:$E$91,">="&A13-1,raw_stand_bench!$E$47:$E$91,"<"&A13+1) -> 0 | D13: =$B$24*(NORMDIST(A13+1,$B$25,$B$26,TRUE())-NORMDIST(A13-1,$B$25,$B$26,TRUE())) -> 1.7755803 | E13: =$C$24*(NORMDIST(A13+1,$C$25,$C$26,TRUE())-NORMDIST(A13-1,$C$25,$C$26,TRUE())) -> 0
... A18: 32 | B18: =COUNTIFS(raw_stand_bench!$E$2:$E$46,">="&A18-1,raw_stand_bench!$E$2:$E$46,"<"&A18+1) -> 0 | C18: =COUNTIFS(raw_stand_bench!$E$47:$E$91,">="&A18-1,raw_stand_bench!$E$47:$E$91,"<"&A18+1) -> 0 | D18: =$B$24*(NORMDIST(A18+1,$B$25,$B$26,TRUE())-NORMDIST(A18-1,$B$25,$B$26,TRUE())) -> 0.045725323 | E18: =$C$24*(NORMDIST(A18+1,$C$25,$C$26,TRUE())-NORMDIST(A18-1,$C$25,$C$26,TRUE())) -> 0
A19: Total | B19: =SUM(B2:B18) -> 45 | C19: =SUM(C2:C18) -> 45
A20: SIMULATION. A 30 s trial counts losses in steps of 2 per minute; each row is one step. 'After' piles up at 0, so its normal fit is only a guide.
A23: Losses per minute | B23: Before | C23: After | D23: Note
A24: n (trials) | B24: =COUNT(raw_stand_bench!$E$2:$E$46) -> 45 | C24: =COUNT(raw_stand_bench!$E$47:$E$91) -> 45
A25: Mean | B25: =AVERAGE(raw_stand_bench!$E$2:$E$46) -> 12.355556 | C25: =AVERAGE(raw_stand_bench!$E$47:$E$91) -> 1.1555556
A26: SD | B26: =STDEV(raw_stand_bench!$E$2:$E$46) -> 6.2999118 | C26: =STDEV(raw_stand_bench!$E$47:$E$91) -> 1.6781423
A27: 95% CI half-width | B27: =TINV(0.05,B24-1)*B26/SQRT(B24) -> 1.892703 | C27: =TINV(0.05,C24-1)*C26/SQRT(C24) -> 0.50416976
A28: 95% CI low | B28: =B25-B27 -> 10.462853 | C28: =C25-C27 -> 0.65138579
A29: 95% CI high | B29: =B25+B27 -> 14.248259 | C29: =C25+C27 -> 1.6597253
A30: Trials with 0 losses | B30: =COUNTIF(raw_stand_bench!$E$2:$E$46,0) -> 1 | C30: =COUNTIF(raw_stand_bench!$E$47:$E$91,0) -> 27
A32: Difference of means | B32: =C25-B25 -> -11.2
A33: Change (%) | B33: =100*(C25/B25-1) -> -90.647482
A34: Welch t | B34: =(B25-C25)/SQRT(B26^2/B24+C26^2/C24) -> 11.52402
A35: Welch df | B35: =(B26^2/B24+C26^2/C24)^2/((B26^2/B24)^2/(B24-1)+(C26^2/C24)^2/(C24-1)) -> 50.212841
A36: Welch p (two-sided) | B36: =TDIST(ABS(B34),B35,2) -> 1.0996243e-15
A37: Cohen's d | B37: =(B25-C25)/SQRT((B26^2+C26^2)/2) -> 2.4294768 | D37: > 0.8 = large
A38: Mann-Whitney U p | B38: 6e-15 | D38: scipy (make_graphs.py)
A40: Other metric | B40: Before_mean | C40: Before_SD | D40: After_mean | E40: After_SD
A41: Jumps per min | B41: =1*AVERAGE(raw_stand_bench!$F$2:$F$46) -> 3.7333333 | C41: =1*STDEV(raw_stand_bench!$F$2:$F$46) -> 3.6828842 | D41: =1*AVERAGE(raw_stand_bench!$F$47:$F$91) -> 0 | E41: =1*STDEV(raw_stand_bench!$F$47:$F$91) -> 0
A42: On the hole (%) | B42: =100*AVERAGE(raw_stand_bench!$G$2:$G$46) -> 87.426667 | C42: =100*STDEV(raw_stand_bench!$G$2:$G$46) -> 8.5577822 | D42: =100*AVERAGE(raw_stand_bench!$G$47:$G$91) -> 99.242222 | E42: =100*STDEV(raw_stand_bench!$G$47:$G$91) -> 1.2278009
A43: Two-box fix (%) | B43: =100*AVERAGE(raw_stand_bench!$H$2:$H$46) -> 82.12 | C43: =100*STDEV(raw_stand_bench!$H$2:$H$46) -> 7.4477147 | D43: =100*AVERAGE(raw_stand_bench!$H$47:$H$91) -> 96.78 | E43: =100*STDEV(raw_stand_bench!$H$47:$H$91) -> 2.7163311
A44: Cursor shown (%) | B44: =100*AVERAGE(raw_stand_bench!$I$2:$I$46) -> 95.973333 | C44: =100*STDEV(raw_stand_bench!$I$2:$I$46) -> 3.379645 | D44: =100*AVERAGE(raw_stand_bench!$I$47:$I$91) -> 99.875556 | E44: =100*STDEV(raw_stand_bench!$I$47:$I$91) -> 0.22779133
A46: SIMULATION. Source: raw_stand_bench (data/raw/stand-bench-2026-10-05.csv), 15 holes x 3 seeds x 30 s. Before = V2 @ 3191700, after = ghost-echo fix aee8ef0.

Sheet 11 Jump dist
A1: Variant | B1: n | C1: Mean_s | D1: SD_s | E1: CI95_half_s | F1: Median_s | G1: P95_s | H1: Max_s
A2: Before | B2: =COUNT(raw_jump!$F$2:$F$161) -> 160 | C2: =AVERAGE(raw_jump!$F$2:$F$161) -> 3.497875 | D2: =STDEV(raw_jump!$F$2:$F$161) -> 2.9196205 | E2: =TINV(0.05,B2-1)*D2/SQRT(B2) -> 0.45586126 | F2: =MEDIAN(raw_jump!$F$2:$F$161) -> 3.395 | G2: =PERCENTILE(raw_jump!$F$2:$F$161,0.95) -> 9.1405 | H2: =MAX(raw_jump!$F$2:$F$161) -> 9.25
A3: Search after loss | B3: =COUNT(raw_jump!$F$162:$F$321) -> 160 | C3: =AVERAGE(raw_jump!$F$162:$F$321) -> 1.2095 | D3: =STDEV(raw_jump!$F$162:$F$321) -> 0.45367514 | E3: =TINV(0.05,B3-1)*D3/SQRT(B3) -> 0.070835548 | F3: =MEDIAN(raw_jump!$F$162:$F$321) -> 1.32 | G3: =PERCENTILE(raw_jump!$F$162:$F$321,0.95) -> 1.88 | H3: =MAX(raw_jump!$F$162:$F$321) -> 1.92
A4: Search, wrong hint | B4: =COUNT(raw_jump!$F$322:$F$481) -> 160 | C4: =AVERAGE(raw_jump!$F$322:$F$481) -> 1.22175 | D4: =STDEV(raw_jump!$F$322:$F$481) -> 0.45530769 | E4: =TINV(0.05,B4-1)*D4/SQRT(B4) -> 0.07109045 | F4: =MEDIAN(raw_jump!$F$322:$F$481) -> 1.36 | G4: =PERCENTILE(raw_jump!$F$322:$F$481,0.95) -> 1.8205 | H4: =MAX(raw_jump!$F$322:$F$481) -> 2.08
A5: Search, right hint | B5: =COUNT(raw_jump!$F$482:$F$641) -> 160 | C5: =AVERAGE(raw_jump!$F$482:$F$641) -> 0.848375 | D5: =STDEV(raw_jump!$F$482:$F$641) -> 0.21708152 | E5: =TINV(0.05,B5-1)*D5/SQRT(B5) -> 0.033894492 | F5: =MEDIAN(raw_jump!$F$482:$F$641) -> 0.86 | G5: =PERCENTILE(raw_jump!$F$482:$F$641,0.95) -> 1.3105 | H5: =MAX(raw_jump!$F$482:$F$641) -> 1.46
A7: Before vs search after loss | B7: Value | C7: Note
A8: Welch t | B8: =(C2-C3)/SQRT(D2^2/B2+D3^2/B3) -> 9.7967028
A9: Welch df | B9: =(D2^2/B2+D3^2/B3)^2/((D2^2/B2)^2/(B2-1)+(D3^2/B3)^2/(B3-1)) -> 166.67381
A10: Welch p (two-sided) | B10: =TDIST(ABS(B8),B9,2) -> 3.6163467e-18
A11: Levene p (spread) | B11: 1e-34 | C11: scipy.stats.levene (make_graphs.py)
A12: SD ratio before / search | B12: =D2/D3 -> 6.4354872
A13: SIMULATION. 'Before' falls in separate clusters (one per jump direction and row), so its normal fit is poor; read P95 from the data.
A15: Bin_from_s | B15: Bin_mid_s | C15: Before | D15: Search after loss | E15: Search, wrong hint | F15: Search, right hint | G15: Before fit | H15: Search after loss fit | I15: Search, wrong hint fit | J15: Search, right hint fit
A16: 0 | B16: =A16+0.125 -> 0.125 | C16: =COUNTIFS(raw_jump!$F$2:$F$161,">="&A16,raw_jump!$F$2:$F$161,"<"&A16+0.25) -> 0 | D16: =COUNTIFS(raw_jump!$F$162:$F$321,">="&A16,raw_jump!$F$162:$F$321,"<"&A16+0.25) -> 0 | E16: =COUNTIFS(raw_jump!$F$322:$F$481,">="&A16,raw_jump!$F$322:$F$481,"<"&A16+0.25) -> 0 | F16: =COUNTIFS(raw_jump!$F$482:$F$641,">="&A16,raw_jump!$F$482:$F$641,"<"&A16+0.25) -> 0 | G16: =$B$2*(NORMDIST(A16+0.25,$C$2,$D$2,TRUE())-NORMDIST(A16,$C$2,$D$2,TRUE())) -> 2.8046947 | H16: =$B$3*(NORMDIST(A16+0.25,$C$3,$D$3,TRUE())-NORMDIST(A16,$C$3,$D$3,TRUE())) -> 2.1406711 | I16: =$B$4*(NORMDIST(A16+0.25,$C$4,$D$4,TRUE())-NORMDIST(A16,$C$4,$D$4,TRUE())) -> 2.0425394 | J16: =$B$5*(NORMDIST(A16+0.25,$C$5,$D$5,TRUE())-NORMDIST(A16,$C$5,$D$5,TRUE())) -> 0.46001397
A17: 0.25 | B17: =A17+0.125 -> 0.375 | C17: =COUNTIFS(raw_jump!$F$2:$F$161,">="&A17,raw_jump!$F$2:$F$161,"<"&A17+0.25) -> 1 | D17: =COUNTIFS(raw_jump!$F$162:$F$321,">="&A17,raw_jump!$F$162:$F$321,"<"&A17+0.25) -> 1 | E17: =COUNTIFS(raw_jump!$F$322:$F$481,">="&A17,raw_jump!$F$322:$F$481,"<"&A17+0.25) -> 1 | F17: =COUNTIFS(raw_jump!$F$482:$F$641,">="&A17,raw_jump!$F$482:$F$641,"<"&A17+0.25) -> 1 | G17: =$B$2*(NORMDIST(A17+0.25,$C$2,$D$2,TRUE())-NORMDIST(A17,$C$2,$D$2,TRUE())) -> 3.0848136 | H17: =$B$3*(NORMDIST(A17+0.25,$C$3,$D$3,TRUE())-NORMDIST(A17,$C$3,$D$3,TRUE())) -> 6.6726497 | I17: =$B$4*(NORMDIST(A17+0.25,$C$4,$D$4,TRUE())-NORMDIST(A17,$C$4,$D$4,TRUE())) -> 6.4081735 | J17: =$B$5*(NORMDIST(A17+0.25,$C$5,$D$5,TRUE())-NORMDIST(A17,$C$5,$D$5,TRUE())) -> 8.215361
A18: 0.5 | B18: =A18+0.125 -> 0.625 | C18: =COUNTIFS(raw_jump!$F$2:$F$161,">="&A18,raw_jump!$F$2:$F$161,"<"&A18+0.25) -> 46 | D18: =COUNTIFS(raw_jump!$F$162:$F$321,">="&A18,raw_jump!$F$162:$F$321,"<"&A18+0.25) -> 46 | E18: =COUNTIFS(raw_jump!$F$322:$F$481,">="&A18,raw_jump!$F$322:$F$481,"<"&A18+0.25) -> 46 | F18: =COUNTIFS(raw_jump!$F$482:$F$641,">="&A18,raw_jump!$F$482:$F$641,"<"&A18+0.25) -> 46 | G18: =$B$2*(NORMDIST(A18+0.25,$C$2,$D$2,TRUE())-NORMDIST(A18,$C$2,$D$2,TRUE())) -> 3.3681383 | H18: =$B$3*(NORMDIST(A18+0.25,$C$3,$D$3,TRUE())-NORMDIST(A18,$C$3,$D$3,TRUE())) -> 15.463565 | I18: =$B$4*(NORMDIST(A18+0.25,$C$4,$D$4,TRUE())-NORMDIST(A18,$C$4,$D$4,TRUE())) -> 14.97815 | J18: =$B$5*(NORMDIST(A18+0.25,$C$5,$D$5,TRUE())-NORMDIST(A18,$C$5,$D$5,TRUE())) -> 43.351245
A19: 0.75 | B19: =A19+0.125 -> 0.875 | C19: =COUNTIFS(raw_jump!$F$2:$F$161,">="&A19,raw_jump!$F$2:$F$161,"<"&A19+0.25) -> 0 | D19: =COUNTIFS(raw_jump!$F$162:$F$321,">="&A19,raw_jump!$F$162:$F$321,"<"&A19+0.25) -> 0 | E19: =COUNTIFS(raw_jump!$F$322:$F$481,">="&A19,raw_jump!$F$322:$F$481,"<"&A19+0.25) -> 0 | F19: =COUNTIFS(raw_jump!$F$482:$F$641,">="&A19,raw_jump!$F$482:$F$641,"<"&A19+0.25) -> 87 | G19: =$B$2*(NORMDIST(A19+0.25,$C$2,$D$2,TRUE())-NORMDIST(A19,$C$2,$D$2,TRUE())) -> 3.6506364 | H19: =$B$3*(NORMDIST(A19+0.25,$C$3,$D$3,TRUE())-NORMDIST(A19,$C$3,$D$3,TRUE())) -> 26.647933 | I19: =$B$4*(NORMDIST(A19+0.25,$C$4,$D$4,TRUE())-NORMDIST(A19,$C$4,$D$4,TRUE())) -> 26.086807 | J19: =$B$5*(NORMDIST(A19+0.25,$C$5,$D$5,TRUE())-NORMDIST(A19,$C$5,$D$5,TRUE())) -> 69.175289
A20: 1 | B20: =A20+0.125 -> 1.125 | C20: =COUNTIFS(raw_jump!$F$2:$F$161,">="&A20,raw_jump!$F$2:$F$161,"<"&A20+0.25) -> 20 | D20: =COUNTIFS(raw_jump!$F$162:$F$321,">="&A20,raw_jump!$F$162:$F$321,"<"&A20+0.25) -> 24 | E20: =COUNTIFS(raw_jump!$F$322:$F$481,">="&A20,raw_jump!$F$322:$F$481,"<"&A20+0.25) -> 13 | F20: =COUNTIFS(raw_jump!$F$482:$F$641,">="&A20,raw_jump!$F$482:$F$641,"<"&A20+0.25) -> 13 | G20: =$B$2*(NORMDIST(A20+0.25,$C$2,$D$2,TRUE())-NORMDIST(A20,$C$2,$D$2,TRUE())) -> 3.9279404 | H20: =$B$3*(NORMDIST(A20+0.25,$C$3,$D$3,TRUE())-NORMDIST(A20,$C$3,$D$3,TRUE())) -> 34.151784 | I20: =$B$4*(NORMDIST(A20+0.25,$C$4,$D$4,TRUE())-NORMDIST(A20,$C$4,$D$4,TRUE())) -> 33.859121 | J20: =$B$5*(NORMDIST(A20+0.25,$C$5,$D$5,TRUE())-NORMDIST(A20,$C$5,$D$5,TRUE())) -> 33.646849
A21: 1.25 | B21: =A21+0.125 -> 1.375 | C21: =COUNTIFS(raw_jump!$F$2:$F$161,">="&A21,raw_jump!$F$2:$F$161,"<"&A21+0.25) -> 0 | D21: =COUNTIFS(raw_jump!$F$162:$F$321,">="&A21,raw_jump!$F$162:$F$321,"<"&A21+0.25) -> 46 | E21: =COUNTIFS(raw_jump!$F$322:$F$481,">="&A21,raw_jump!$F$322:$F$481,"<"&A21+0.25) -> 58 | F21: =COUNTIFS(raw_jump!$F$482:$F$641,">="&A21,raw_jump!$F$482:$F$641,"<"&A21+0.25) -> 13 | G21: =$B$2*(NORMDIST(A21+0.25,$C$2,$D$2,TRUE())-NORMDIST(A21,$C$2,$D$2,TRUE())) -> 4.1954531 | H21: =$B$3*(NORMDIST(A21+0.25,$C$3,$D$3,TRUE())-NORMDIST(A21,$C$3,$D$3,TRUE())) -> 32.552475 | I21: =$B$4*(NORMDIST(A21+0.25,$C$4,$D$4,TRUE())-NORMDIST(A21,$C$4,$D$4,TRUE())) -> 32.752763 | J21: =$B$5*(NORMDIST(A21+0.25,$C$5,$D$5,TRUE())-NORMDIST(A21,$C$5,$D$5,TRUE())) -> 4.9290552
A22: 1.5 | B22: =A22+0.125 -> 1.625 | C22: =COUNTIFS(raw_jump!$F$2:$F$161,">="&A22,raw_jump!$F$2:$F$161,"<"&A22+0.25) -> 0 | D22: =COUNTIFS(raw_jump!$F$162:$F$321,">="&A22,raw_jump!$F$162:$F$321,"<"&A22+0.25) -> 16 | E22: =COUNTIFS(raw_jump!$F$322:$F$481,">="&A22,raw_jump!$F$322:$F$481,"<"&A22+0.25) -> 25 | F22: =COUNTIFS(raw_jump!$F$482:$F$641,">="&A22,raw_jump!$F$482:$F$641,"<"&A22+0.25) -> 0 | G22: =$B$2*(NORMDIST(A22+0.25,$C$2,$D$2,TRUE())-NORMDIST(A22,$C$2,$D$2,TRUE())) -> 4.4484685 | H22: =$B$3*(NORMDIST(A22+0.25,$C$3,$D$3,TRUE())-NORMDIST(A22,$C$3,$D$3,TRUE())) -> 23.076533 | I22: =$B$4*(NORMDIST(A22+0.25,$C$4,$D$4,TRUE())-NORMDIST(A22,$C$4,$D$4,TRUE())) -> 23.61209 | J22: =$B$5*(NORMDIST(A22+0.25,$C$5,$D$5,TRUE())-NORMDIST(A22,$C$5,$D$5,TRUE())) -> 0.21212361
