Workbook

Sheet Overview
A1: Tracking subsystem <-> game subsystem: how they integrate
A2: Real field data from runtime-logs/game.log* (5-6 Oct 2026, real ESP32 boxes). All numbers below are live formulas over the data sheets.
B4: Key numbers
B5: Rounds analysed (real boxes) | D5: =COUNT(Rounds!A5:A21) -> 17
B6: Play time (min) | D6: =SUM(Rounds!E5:E21)/60 -> 23.303633
B7: Tracker polls per second (= game frames) | D7: =Constants!B10 -> 60
B8: Hits registered (mole + king) | D8: =SUM(Rounds!I5:J21) -> 94
B9: Hits with cursor inside the hole ellipse | D9: =Hits!U7 -> 1
B10: Tracker losses (all rounds) | D10: =SUM(Rounds!L5:L21) -> 323
B11: Losses per minute: before -> after ghost-echo fix | D11: =TEXT(Rounds!F26,"0.0")&" -> "&TEXT(Rounds!F27,"0.0") -> 12.1 -> 14.4 | E11: Not like for like: after-fix rounds had much more movement (see Rounds, Hits / min). Standing still improved; moving play still loses the player ~14 times/min.
B12: Median reacquire (s): before -> after fix | D12: =TEXT(Losses!L14,"0.00")&" -> "&TEXT(Losses!M14,"0.00") -> 0.28 -> 0.39 | E12: Short losses (< 1 s) cost the player nothing: the cursor still counts during the 1 s grace.
B13: Time with a position (1 or 2+ boxes), after fix | D13: =Rounds!H27+Rounds!I27 -> 0.4907321
B16: Data flow, one game frame (every 1/60 s)
B17: Step | C17: Where (file / function) | D17: What happens | E17: Passes on | F17: Evidence in this workbook | G17: Direction
B18: 1. Boxes measure | C18: firmware/ on ESP32 (tracker repo) | D18: Servo aims, HC-SR04 pings, reply over UDP 4210 (WM2 protocol) | E18: Range + bearing per box | F18: Box Health | G18: Boxes -> laptop
B19: 2. Tracker decides | C19: software/tracker/swarm.py SwarmController.poll() | D19: Sweep / aim / fuse ranges (least squares) / reject static echoes / declare loss | E19: Snapshot: position, state, alert, contributors | F19: Timeline, Losses | G19: Inside tracker
B20: 3. Adapter maps | C20: software/game/swarm_tracking.py SwarmTrackingSource.poll() | D20: Mirror x (game_x = 1.50 - tracker_x), clamp/reject far fixes, map status | E20: PLAYABLE / WAITING / TRACKING_LOST / DEAD_ZONE | F20: Timeline (category) | G20: Tracker -> game
B21: 4. Game smooths | C21: main.py update_active_phase() + interpolate_position | D21: Smoothed cursor for drawing and contact; warning judged on raw fix | E21: Cursor (m) -> pixels | F21: Cursor Path | G21: Inside game
B22: 5. Contact test | C22: main.py contact_hole() | D22: Cursor inside hole ellipse (0.345 m x 0.28 m)? | E22: GameInput(contacted_holes) | F22: Hits (normalised distance) | G22: Inside game
B23: 6. Gameplay | C23: software/gameplay game.step() | D23: Mole hit, score, level up; never imports the tracker | E23: Events (mole_hit, level up) | F23: Hits, Rounds | G23: Inside game
B24: 7. Game -> tracker | C24: SwarmTrackingSource.expect_game_point / start_for_round / park | D24: Newest mole hole as search hint; start search at round start; park servos on pause/end | E24: Hint point (tracker frame), commands | F24: Timeline (Paused rows) | G24: Game -> tracker
B25: 8. Display | C25: godot_frontend.py -> Godot over UDP 47810 (or Pygame) | D25: Draws the frame; sends keys back | E25: Frame state | F25: - | G25: Game -> view
B27: Status mapping (tracker Snapshot -> game status -> what the round does)
B28: Tracker reports | C28: Game status | D28: Round behaviour | E28: Cursor counts for hits? | F28: Share of field time
B29: Fix inside field (+0.10 m two-box / +0.40 m one-box margin), 2+ boxes | C29: PLAYABLE | D29: Plays normally | E29: Yes | F29: =Rounds!H28 -> 0.42868923
B30: Same, coarse one-box fix | C30: PLAYABLE | D30: Plays normally | E30: Yes | F30: =Rounds!I28 -> 0.14765794
B31: No fix after a fix (state 'find', 'Searching') | C31: TRACKING_LOST | D31: Round runs on; cursor held; no contact after 1 s grace | E31: Only within grace | F31: =Rounds!J28 -> 0.18039749
B32: Alert: too close / dead zone / two players | C32: DEAD_ZONE (too close) or shown only | D32: Screen-warning pause for too close; others are shown only | E32: No (too close) | F32: =Rounds!K28 -> 0.063830536
B33: Tracker parked by the game (pause, round over), calibrating | C33: WAITING / LOST | D33: Round paused by the game | E33: No | F33: =Rounds!L28 -> 0.17942481
B35: Sheets
B36: Dashboard | C36: All charts (native Excel charts on the data sheets)
B37: Rounds | C37: One row per field round; summary before/after the ghost-echo fix
B38: Timeline | C38: Tracker status stretches with each box's reading
B39: Losses | C39: Every tracker loss and its reacquire time, histogram
B40: Hits | C40: Every hit checked against the hole ellipse (proves tracker -> contact -> score chain)
B41: Cursor Path | C41: Full cursor stream of the best round; update-gap histogram
B42: Box Health | C42: Share of time each box gave a range
B43: Bench V1 vs V2 | C43: Tracker-only bench that motivated the search-after-loss change
B44: Constants | C44: Field size, contact ellipse, frame rate, hole layouts (inputs)
B45: Sources | C45: Where every number comes from, and the assumptions

Sheet Dashboard
A1: Dashboard
A2: Native Excel charts; each one reads the data sheet named in its title.

Sheet Constants
A1: Constants and hole layouts
A2: Inputs used by the formulas on the other sheets. Blue = typed-in value, black = formula.
A4: Constant | B4: Value | C4: Unit | D4: Source in code
A5: Field width | B5: 1.5 | C5: m | D5: software/game/field_constants.py PLAY_AREA_WIDTH_M
A6: Tracked depth | B6: 2 | C6: m | D6: field_constants.py TRACKED_DEPTH_M
A7: Dead zone / screen warning depth | B7: 0.6 | C7: m | D7: field_constants.py PLAY_AREA_TOP_M
A8: Hole contact half-width | B8: =0.115*B5 -> 0.1725 | C8: m | D8: main.py HOLE_CONTACT_HALF_WIDTH = 0.115 of window width
A9: Hole contact half-depth | B9: =0.07*B6 -> 0.14 | C9: m | D9: main.py HOLE_CONTACT_HALF_DEPTH = 0.07 of window height
A10: Game frame rate (tracker poll rate) | B10: 60 | C10: Hz | D10: main.py FRAME_RATE; SwarmTrackingSource.poll() runs once per frame
A11: Frame period | B11: =1000/B10 -> 16.666667 | C11: ms | D11: derived
A12: Tracking-loss grace | B12: 1000 | C12: ms | D12: main.py TRACKING_LOSS_GRACE_MS: cursor still counts this long after a fix
A13: Ghost-echo fix deployed | B13: 46300.151 | C13: time | D13: game commit 2506fce (tracker sync aee8ef0), 2026-10-05 03:37
A16: Hole centres by layout (game frame: x from player's left, y from the screen wall)
A17: Key | B17: Layout | C17: Hole | D17: x (m) | E17: y (m)
A18: =B18&"#"&C18 -> 3-3-3#0 | B18: 3-3-3 | C18: 0 | D18: 0.25 | E18: 1.1
A19: =B19&"#"&C19 -> 3-3-3#1 | B19: 3-3-3 | C19: 1 | D19: 0.75 | E19: 1.1
A20: =B20&"#"&C20 -> 3-3-3#2 | B20: 3-3-3 | C20: 2 | D20: 1.25 | E20: 1.1
A21: =B21&"#"&C21 -> 3-3-3#3 | B21: 3-3-3 | C21: 3 | D21: 0.25 | E21: 1.45
A22: =B22&"#"&C22 -> 3-3-3#4 | B22: 3-3-3 | C22: 4 | D22: 0.75 | E22: 1.45
A23: =B23&"#"&C23 -> 3-3-3#5 | B23: 3-3-3 | C23: 5 | D23: 1.25 | E23: 1.45
A24: =B24&"#"&C24 -> 3-3-3#6 | B24: 3-3-3 | C24: 6 | D24: 0.25 | E24: 1.8
A25: =B25&"#"&C25 -> 3-3-3#7 | B25: 3-3-3 | C25: 7 | D25: 0.75 | E25: 1.8
A26: =B26&"#"&C26 -> 3-3-3#8 | B26: 3-3-3 | C26: 8 | D26: 1.25 | E26: 1.8
A27: =B27&"#"&C27 -> 2-3-2#0 | B27: 2-3-2 | C27: 0 | D27: 0.5 | E27: 1.1
A28: =B28&"#"&C28 -> 2-3-2#1 | B28: 2-3-2 | C28: 1 | D28: 1 | E28: 1.1
A29: =B29&"#"&C29 -> 2-3-2#2 | B29: 2-3-2 | C29: 2 | D29: 0.25 | E29: 1.42
... A41: =B41&"#"&C41 -> 3-2-3#7 | B41: 3-2-3 | C41: 7 | D41: 1.25 | E41: 1.74
A42: Source: software/game/hole_layouts.hole_positions_m() on branch CamHaoHa/grid-first-slower-moles @b7874bc.

Sheet Rounds
A1: Field rounds with the real boxes
A2: One row per complete round (time_up) from runtime-logs/game.log*. Counts and shares are formulas over the Timeline, Losses and Hits sheets.
P3: Tracking, 2+ boxes fused | Q3: Tracking, one box | R3: Searching (lost) | S3: Tracker alert | T3: Paused / calibrating
A4: Round | B4: Date | C4: Start | D4: End | E4: Duration (s) | F4: Tracker build | G4: Score | H4: Level reached | I4: Mole hits | J4: King hits | K4: Hits / min | L4: Tracker losses | M4: Losses / min | N4: Mean reacquire (s) | O4: Longest loss (s) | P4: % Tracking, 2+ boxes fused | Q4: % Tracking, one box | R4: % Searching (lost) | S4: % Tracker alert | T4: % Paused / calibrating | U4: % check | V4: Cursor updates | W4: Position jumps | X4: Run header in log
A5: 1 | B5: =TEXT(C5,"yyyy-mm-dd") -> 2026-10-05 | C5: 46300.111 | D5: 46300.112 | E5: =(D5-C5)*86400 -> 67.863 | F5: =IF(C5<Constants!$B$13,"Before fix","After fix") -> Before fix | G5: 400 | H5: 2 | I5: =COUNTIFS(Hits!$A:$A,$A5,Hits!$D:$D,"mole_hit") -> 4 | J5: =COUNTIFS(Hits!$A:$A,$A5,Hits!$D:$D,"king_hit") -> 0 | K5: =(I5+J5)/(E5/60) -> 3.5365368 | L5: =COUNTIF(Losses!$A:$A,$A5) -> 10 | M5: =L5/(E5/60) -> 8.8413421 | N5: =IFERROR(AVERAGEIF(Losses!$A:$A,$A5,Losses!$F:$F),0) -> 0.47900005 | O5: =IFERROR(_xlfn.MAXIFS(Losses!$F:$F,Losses!$A:$A,$A5),0) -> 1.804001 | P5: =SUMIFS(Timeline!$F:$F,Timeline!$A:$A,$A5,Timeline!$G:$G,P$3)/$E5 -> 0.8317492 | Q5: =SUMIFS(Timeline!$F:$F,Timeline!$A:$A,$A5,Timeline!$G:$G,Q$3)/$E5 -> 0.08960706 | R5: =SUMIFS(Timeline!$F:$F,Timeline!$A:$A,$A5,Timeline!$G:$G,R$3)/$E5 -> 0.078643741 | S5: =SUMIFS(Timeline!$F:$F,Timeline!$A:$A,$A5,Timeline!$G:$G,S$3)/$E5 -> 0 | T5: =SUMIFS(Timeline!$F:$F,Timeline!$A:$A,$A5,Timeline!$G:$G,T$3)/$E5 -> 0 | U5: =SUM(P5:T5) -> 1 | V5: 2724 | W5: 0 | X5: Rotated out
A6: 2 | B6: =TEXT(C6,"yyyy-mm-dd") -> 2026-10-05 | C6: 46300.113 | D6: 46300.114 | E6: =(D6-C6)*86400 -> 63.009999 | F6: =IF(C6<Constants!$B$13,"Before fix","After fix") -> Before fix | G6: 200 | H6: 1 | I6: =COUNTIFS(Hits!$A:$A,$A6,Hits!$D:$D,"mole_hit") -> 2 | J6: =COUNTIFS(Hits!$A:$A,$A6,Hits!$D:$D,"king_hit") -> 0 | K6: =(I6+J6)/(E6/60) -> 1.9044596 | L6: =COUNTIF(Losses!$A:$A,$A6) -> 12 | M6: =L6/(E6/60) -> 11.426758 | N6: =IFERROR(AVERAGEIF(Losses!$A:$A,$A6,Losses!$F:$F),0) -> 0.7036669 | O6: =IFERROR(_xlfn.MAXIFS(Losses!$F:$F,Losses!$A:$A,$A6),0) -> 1.529 | P6: =SUMIFS(Timeline!$F:$F,Timeline!$A:$A,$A6,Timeline!$G:$G,P$3)/$E6 -> 0.70749091 | Q6: =SUMIFS(Timeline!$F:$F,Timeline!$A:$A,$A6,Timeline!$G:$G,Q$3)/$E6 -> 0.14786533 | R6: =SUMIFS(Timeline!$F:$F,Timeline!$A:$A,$A6,Timeline!$G:$G,R$3)/$E6 -> 0.14464376 | S6: =SUMIFS(Timeline!$F:$F,Timeline!$A:$A,$A6,Timeline!$G:$G,S$3)/$E6 -> 0 | T6: =SUMIFS(Timeline!$F:$F,Timeline!$A:$A,$A6,Timeline!$G:$G,T$3)/$E6 -> 0 | U6: =SUM(P6:T6) -> 1 | V6: 2364 | W6: 2 | X6: Rotated out
A7: 3 | B7: =TEXT(C7,"yyyy-mm-dd") -> 2026-10-05 | C7: 46300.114 | D7: 46300.115 | E7: =(D7-C7)*86400 -> 63.02 | F7: =IF(C7<Constants!$B$13,"Before fix","After fix") -> Before fix | G7: 100 | H7: 1 | I7: =COUNTIFS(Hits!$A:$A,$A7,Hits!$D:$D,"mole_hit") -> 1 | J7: =COUNTIFS(Hits!$A:$A,$A7,Hits!$D:$D,"king_hit") -> 0 | K7: =(I7+J7)/(E7/60) -> 0.95207871 | L7: =COUNTIF(Losses!$A:$A,$A7) -> 13 | M7: =L7/(E7/60) -> 12.377023 | N7: =IFERROR(AVERAGEIF(Losses!$A:$A,$A7,Losses!$F:$F),0) -> 0.54600006 | O7: =IFERROR(_xlfn.MAXIFS(Losses!$F:$F,Losses!$A:$A,$A7),0) -> 1.6520002 | P7: =SUMIFS(Timeline!$F:$F,Timeline!$A:$A,$A7,Timeline!$G:$G,P$3)/$E7 -> 0.67846713 | Q7: =SUMIFS(Timeline!$F:$F,Timeline!$A:$A,$A7,Timeline!$G:$G,Q$3)/$E7 -> 0.14465251 | R7: =SUMIFS(Timeline!$F:$F,Timeline!$A:$A,$A7,Timeline!$G:$G,R$3)/$E7 -> 0.11973977 | S7: =SUMIFS(Timeline!$F:$F,Timeline!$A:$A,$A7,Timeline!$G:$G,S$3)/$E7 -> 0.057140582 | T7: =SUMIFS(Timeline!$F:$F,Timeline!$A:$A,$A7,Timeline!$G:$G,T$3)/$E7 -> 0 | U7: =SUM(P7:T7) -> 1 | V7: 2030 | W7: 2 | X7: Rotated out
A8: 4 | B8: =TEXT(C8,"yyyy-mm-dd") -> 2026-10-05 | C8: 46300.115 | D8: 46300.116 | E8: =(D8-C8)*86400 -> 70.795 | F8: =IF(C8<Constants!$B$13,"Before fix","After fix") -> Before fix | G8: 0 | H8: 1 | I8: =COUNTIFS(Hits!$A:$A,$A8,Hits!$D:$D,"mole_hit") -> 0 | J8: =COUNTIFS(Hits!$A:$A,$A8,Hits!$D:$D,"king_hit") -> 0 | K8: =(I8+J8)/(E8/60) -> 0 | L8: =COUNTIF(Losses!$A:$A,$A8) -> 17 | M8: =L8/(E8/60) -> 14.407797 | N8: =IFERROR(AVERAGEIF(Losses!$A:$A,$A8,Losses!$F:$F),0) -> 0.49094102 | O8: =IFERROR(_xlfn.MAXIFS(Losses!$F:$F,Losses!$A:$A,$A8),0) -> 2.0249997 | P8: =SUMIFS(Timeline!$F:$F,Timeline!$A:$A,$A8,Timeline!$G:$G,P$3)/$E8 -> 0.62227566 | Q8: =SUMIFS(Timeline!$F:$F,Timeline!$A:$A,$A8,Timeline!$G:$G,Q$3)/$E8 -> 0.14125288 | R8: =SUMIFS(Timeline!$F:$F,Timeline!$A:$A,$A8,Timeline!$G:$G,R$3)/$E8 -> 0.15488378 | S8: =SUMIFS(Timeline!$F:$F,Timeline!$A:$A,$A8,Timeline!$G:$G,S$3)/$E8 -> 0 | T8: =SUMIFS(Timeline!$F:$F,Timeline!$A:$A,$A8,Timeline!$G:$G,T$3)/$E8 -> 0.081587687 | U8: =SUM(P8:T8) -> 1 | V8: 2087 | W8: 1 | X8: Rotated out
A9: 5 | B9: =TEXT(C9,"yyyy-mm-dd") -> 2026-10-05 | C9: 46300.127 | D9: 46300.128 | E9: =(D9-C9)*86400 -> 63.005 | F9: =IF(C9<Constants!$B$13,"Before fix","After fix") -> Before fix | G9: 200 | H9: 1 | I9: =COUNTIFS(Hits!$A:$A,$A9,Hits!$D:$D,"mole_hit") -> 2 | J9: =COUNTIFS(Hits!$A:$A,$A9,Hits!$D:$D,"king_hit") -> 0 | K9: =(I9+J9)/(E9/60) -> 1.9046107 | L9: =COUNTIF(Losses!$A:$A,$A9) -> 14 | M9: =L9/(E9/60) -> 13.332275 | N9: =IFERROR(AVERAGEIF(Losses!$A:$A,$A9,Losses!$F:$F),0) -> 0.29728582 | O9: =IFERROR(_xlfn.MAXIFS(Losses!$F:$F,Losses!$A:$A,$A9),0) -> 1.1589997 | P9: =SUMIFS(Timeline!$F:$F,Timeline!$A:$A,$A9,Timeline!$G:$G,P$3)/$E9 -> 0.80044438 | Q9: =SUMIFS(Timeline!$F:$F,Timeline!$A:$A,$A9,Timeline!$G:$G,Q$3)/$E9 -> 0.12279978 | R9: =SUMIFS(Timeline!$F:$F,Timeline!$A:$A,$A9,Timeline!$G:$G,R$3)/$E9 -> 0.076755837 | S9: =SUMIFS(Timeline!$F:$F,Timeline!$A:$A,$A9,Timeline!$G:$G,S$3)/$E9 -> 0 | T9: =SUMIFS(Timeline!$F:$F,Timeline!$A:$A,$A9,Timeline!$G:$G,T$3)/$E9 -> 0 | U9: =SUM(P9:T9) -> 1 | V9: 1779 | W9: 3 | X9: Yes
A10: 6 | B10: =TEXT(C10,"yyyy-mm-dd") -> 2026-10-05 | C10: 46300.153 | D10: 46300.153 | E10: =(D10-C10)*86400 -> 63.014 | F10: =IF(C10<Constants!$B$13,"Before fix","After fix") -> After fix | G10: 0 | H10: 1 | I10: =COUNTIFS(Hits!$A:$A,$A10,Hits!$D:$D,"mole_hit") -> 0 | J10: =COUNTIFS(Hits!$A:$A,$A10,Hits!$D:$D,"king_hit") -> 0 | K10: =(I10+J10)/(E10/60) -> 0 | L10: =COUNTIF(Losses!$A:$A,$A10) -> 12 | M10: =L10/(E10/60) -> 11.426032 | N10: =IFERROR(AVERAGEIF(Losses!$A:$A,$A10,Losses!$F:$F),0) -> 0.49808328 | O10: =IFERROR(_xlfn.MAXIFS(Losses!$F:$F,Losses!$A:$A,$A10),0) -> 1.1079992 | P10: =SUMIFS(Timeline!$F:$F,Timeline!$A:$A,$A10,Timeline!$G:$G,P$3)/$E10 -> 0.68064243 | Q10: =SUMIFS(Timeline!$F:$F,Timeline!$A:$A,$A10,Timeline!$G:$G,Q$3)/$E10 -> 0.1276224 | R10: =SUMIFS(Timeline!$F:$F,Timeline!$A:$A,$A10,Timeline!$G:$G,R$3)/$E10 -> 0.11449836 | S10: =SUMIFS(Timeline!$F:$F,Timeline!$A:$A,$A10,Timeline!$G:$G,S$3)/$E10 -> 0.077236813 | T10: =SUMIFS(Timeline!$F:$F,Timeline!$A:$A,$A10,Timeline!$G:$G,T$3)/$E10 -> 0 | U10: =SUM(P10:T10) -> 1 | V10: 2333 | W10: 3 | X10: Yes
A11: 7 | B11: =TEXT(C11,"yyyy-mm-dd") -> 2026-10-05 | C11: 46300.154 | D11: 46300.157 | E11: =(D11-C11)*86400 -> 293.336 | F11: =IF(C11<Constants!$B$13,"Before fix","After fix") -> After fix | G11: 500 | H11: 1 | I11: =COUNTIFS(Hits!$A:$A,$A11,Hits!$D:$D,"mole_hit") -> 2 | J11: =COUNTIFS(Hits!$A:$A,$A11,Hits!$D:$D,"king_hit") -> 1 | K11: =(I11+J11)/(E11/60) -> 0.61363079 | L11: =COUNTIF(Losses!$A:$A,$A11) -> 9 | M11: =L11/(E11/60) -> 1.8408924 | N11: =IFERROR(AVERAGEIF(Losses!$A:$A,$A11,Losses!$F:$F),0) -> 0.49777741 | O11: =IFERROR(_xlfn.MAXIFS(Losses!$F:$F,Losses!$A:$A,$A11),0) -> 0.8519995 | P11: =SUMIFS(Timeline!$F:$F,Timeline!$A:$A,$A11,Timeline!$G:$G,P$3)/$E11 -> 0.11079445 | Q11: =SUMIFS(Timeline!$F:$F,Timeline!$A:$A,$A11,Timeline!$G:$G,Q$3)/$E11 -> 0.018306659 | R11: =SUMIFS(Timeline!$F:$F,Timeline!$A:$A,$A11,Timeline!$G:$G,R$3)/$E11 -> 0.017365743 | S11: =SUMIFS(Timeline!$F:$F,Timeline!$A:$A,$A11,Timeline!$G:$G,S$3)/$E11 -> 0.082339021 | T11: =SUMIFS(Timeline!$F:$F,Timeline!$A:$A,$A11,Timeline!$G:$G,T$3)/$E11 -> 0.77119413 | U11: =SUM(P11:T11) -> 1 | V11: 2345 | W11: 2 | X11: Yes
A12: 8 | B12: =TEXT(C12,"yyyy-mm-dd") -> 2026-10-05 | C12: 46300.157 | D12: 46300.158 | E12: =(D12-C12)*86400 -> 65.417 | F12: =IF(C12<Constants!$B$13,"Before fix","After fix") -> After fix | G12: 1800 | H12: 3 | I12: =COUNTIFS(Hits!$A:$A,$A12,Hits!$D:$D,"mole_hit") -> 6 | J12: =COUNTIFS(Hits!$A:$A,$A12,Hits!$D:$D,"king_hit") -> 2 | K12: =(I12+J12)/(E12/60) -> 7.3375422 | L12: =COUNTIF(Losses!$A:$A,$A12) -> 17 | M12: =L12/(E12/60) -> 15.592277 | N12: =IFERROR(AVERAGEIF(Losses!$A:$A,$A12,Losses!$F:$F),0) -> 0.41976461 | O12: =IFERROR(_xlfn.MAXIFS(Losses!$F:$F,Losses!$A:$A,$A12),0) -> 1.3520006 | P12: =SUMIFS(Timeline!$F:$F,Timeline!$A:$A,$A12,Timeline!$G:$G,P$3)/$E12 -> 0.74552489 | Q12: =SUMIFS(Timeline!$F:$F,Timeline!$A:$A,$A12,Timeline!$G:$G,Q$3)/$E12 -> 0.088081086 | R12: =SUMIFS(Timeline!$F:$F,Timeline!$A:$A,$A12,Timeline!$G:$G,R$3)/$E12 -> 0.11819554 | S12: =SUMIFS(Timeline!$F:$F,Timeline!$A:$A,$A12,Timeline!$G:$G,S$3)/$E12 -> 0.048198486 | T12: =SUMIFS(Timeline!$F:$F,Timeline!$A:$A,$A12,Timeline!$G:$G,T$3)/$E12 -> 0 | U12: =SUM(P12:T12) -> 1 | V12: 2680 | W12: 2 | X12: Yes
A13: 9 | B13: =TEXT(C13,"yyyy-mm-dd") -> 2026-10-06 | C13: 46301.482 | D13: 46301.483 | E13: =(D13-C13)*86400 -> 64.204999 | F13: =IF(C13<Constants!$B$13,"Before fix","After fix") -> After fix | G13: 1600 | H13: 2 | I13: =COUNTIFS(Hits!$A:$A,$A13,Hits!$D:$D,"mole_hit") -> 5 | J13: =COUNTIFS(Hits!$A:$A,$A13,Hits!$D:$D,"king_hit") -> 2 | K13: =(I13+J13)/(E13/60) -> 6.5415467 | L13: =COUNTIF(Losses!$A:$A,$A13) -> 23 | M13: =L13/(E13/60) -> 21.493653 | N13: =IFERROR(AVERAGEIF(Losses!$A:$A,$A13,Losses!$F:$F),0) -> 1.0051305 | O13: =IFERROR(_xlfn.MAXIFS(Losses!$F:$F,Losses!$A:$A,$A13),0) -> 4.3649997 | P13: =SUMIFS(Timeline!$F:$F,Timeline!$A:$A,$A13,Timeline!$G:$G,P$3)/$E13 -> 0.2446227 | Q13: =SUMIFS(Timeline!$F:$F,Timeline!$A:$A,$A13,Timeline!$G:$G,Q$3)/$E13 -> 0.2486099 | R13: =SUMIFS(Timeline!$F:$F,Timeline!$A:$A,$A13,Timeline!$G:$G,R$3)/$E13 -> 0.47300055 | S13: =SUMIFS(Timeline!$F:$F,Timeline!$A:$A,$A13,Timeline!$G:$G,S$3)/$E13 -> 0.033751276 | T13: =SUMIFS(Timeline!$F:$F,Timeline!$A:$A,$A13,Timeline!$G:$G,T$3)/$E13 -> 1.5577759e-05 | U13: =SUM(P13:T13) -> 1 | V13: 1237 | W13: 0 | X13: Yes
A14: 10 | B14: =TEXT(C14,"yyyy-mm-dd") -> 2026-10-06 | C14: 46301.483 | D14: 46301.484 | E14: =(D14-C14)*86400 -> 66.611 | F14: =IF(C14<Constants!$B$13,"Before fix","After fix") -> After fix | G14: 4400 | H14: 4 | I14: =COUNTIFS(Hits!$A:$A,$A14,Hits!$D:$D,"mole_hit") -> 11 | J14: =COUNTIFS(Hits!$A:$A,$A14,Hits!$D:$D,"king_hit") -> 3 | K14: =(I14+J14)/(E14/60) -> 12.61053 | L14: =COUNTIF(Losses!$A:$A,$A14) -> 21 | M14: =L14/(E14/60) -> 18.915795 | N14: =IFERROR(AVERAGEIF(Losses!$A:$A,$A14,Losses!$F:$F),0) -> 0.82104756 | O14: =IFERROR(_xlfn.MAXIFS(Losses!$F:$F,Losses!$A:$A,$A14),0) -> 2.4300009 | P14: =SUMIFS(Timeline!$F:$F,Timeline!$A:$A,$A14,Timeline!$G:$G,P$3)/$E14 -> 0.50316013 | Q14: =SUMIFS(Timeline!$F:$F,Timeline!$A:$A,$A14,Timeline!$G:$G,Q$3)/$E14 -> 0.22422727 | R14: =SUMIFS(Timeline!$F:$F,Timeline!$A:$A,$A14,Timeline!$G:$G,R$3)/$E14 -> 0.2726126 | S14: =SUMIFS(Timeline!$F:$F,Timeline!$A:$A,$A14,Timeline!$G:$G,S$3)/$E14 -> 0 | T14: =SUMIFS(Timeline!$F:$F,Timeline!$A:$A,$A14,Timeline!$G:$G,T$3)/$E14 -> 0 | U14: =SUM(P14:T14) -> 1 | V14: 2168 | W14: 0 | X14: Yes
A15: 11 | B15: =TEXT(C15,"yyyy-mm-dd") -> 2026-10-06 | C15: 46301.485 | D15: 46301.486 | E15: =(D15-C15)*86400 -> 65.414999 | F15: =IF(C15<Constants!$B$13,"Before fix","After fix") -> After fix | G15: 2400 | H15: 3 | I15: =COUNTIFS(Hits!$A:$A,$A15,Hits!$D:$D,"mole_hit") -> 8 | J15: =COUNTIFS(Hits!$A:$A,$A15,Hits!$D:$D,"king_hit") -> 2 | K15: =(I15+J15)/(E15/60) -> 9.1722083 | L15: =COUNTIF(Losses!$A:$A,$A15) -> 34 | M15: =L15/(E15/60) -> 31.185508 | N15: =IFERROR(AVERAGEIF(Losses!$A:$A,$A15,Losses!$F:$F),0) -> 0.77567656 | O15: =IFERROR(_xlfn.MAXIFS(Losses!$F:$F,Losses!$A:$A,$A15),0) -> 5.5080004 | P15: =SUMIFS(Timeline!$F:$F,Timeline!$A:$A,$A15,Timeline!$G:$G,P$3)/$E15 -> 0.29083543 | Q15: =SUMIFS(Timeline!$F:$F,Timeline!$A:$A,$A15,Timeline!$G:$G,Q$3)/$E15 -> 0.22964149 | R15: =SUMIFS(Timeline!$F:$F,Timeline!$A:$A,$A15,Timeline!$G:$G,R$3)/$E15 -> 0.42158531 | S15: =SUMIFS(Timeline!$F:$F,Timeline!$A:$A,$A15,Timeline!$G:$G,S$3)/$E15 -> 0.057937778 | T15: =SUMIFS(Timeline!$F:$F,Timeline!$A:$A,$A15,Timeline!$G:$G,T$3)/$E15 -> 0 | U15: =SUM(P15:T15) -> 1 | V15: 1739 | W15: 0 | X15: Yes
A16: 12 | B16: =TEXT(C16,"yyyy-mm-dd") -> 2026-10-06 | C16: 46301.486 | D16: 46301.487 | E16: =(D16-C16)*86400 -> 77.778999 | F16: =IF(C16<Constants!$B$13,"Before fix","After fix") -> After fix | G16: 1400 | H16: 2 | I16: =COUNTIFS(Hits!$A:$A,$A16,Hits!$D:$D,"mole_hit") -> 6 | J16: =COUNTIFS(Hits!$A:$A,$A16,Hits!$D:$D,"king_hit") -> 1 | K16: =(I16+J16)/(E16/60) -> 5.3999152 | L16: =COUNTIF(Losses!$A:$A,$A16) -> 29 | M16: =L16/(E16/60) -> 22.371077 | N16: =IFERROR(AVERAGEIF(Losses!$A:$A,$A16,Losses!$F:$F),0) -> 0.67058645 | O16: =IFERROR(_xlfn.MAXIFS(Losses!$F:$F,Losses!$A:$A,$A16),0) -> 2.3750003 | P16: =SUMIFS(Timeline!$F:$F,Timeline!$A:$A,$A16,Timeline!$G:$G,P$3)/$E16 -> 0.29128678 | Q16: =SUMIFS(Timeline!$F:$F,Timeline!$A:$A,$A16,Timeline!$G:$G,Q$3)/$E16 -> 0.26424867 | R16: =SUMIFS(Timeline!$F:$F,Timeline!$A:$A,$A16,Timeline!$G:$G,R$3)/$E16 -> 0.24657052 | S16: =SUMIFS(Timeline!$F:$F,Timeline!$A:$A,$A16,Timeline!$G:$G,S$3)/$E16 -> 0.04919065 | T16: =SUMIFS(Timeline!$F:$F,Timeline!$A:$A,$A16,Timeline!$G:$G,T$3)/$E16 -> 0.14870338 | U16: =SUM(P16:T16) -> 1 | V16: 2028 | W16: 1 | X16: Yes
... A21: 17 | B21: =TEXT(C21,"yyyy-mm-dd") -> 2026-10-06 | C21: 46301.526 | D21: 46301.527 | E21: =(D21-C21)*86400 -> 97.159001 | F21: =IF(C21<Constants!$B$13,"Before fix","After fix") -> After fix | G21: 100 | H21: 1 | I21: =COUNTIFS(Hits!$A:$A,$A21,Hits!$D:$D,"mole_hit") -> 1 | J21: =COUNTIFS(Hits!$A:$A,$A21,Hits!$D:$D,"king_hit") -> 0 | K21: =(I21+J21)/(E21/60) -> 0.61754443 | L21: =COUNTIF(Losses!$A:$A,$A21) -> 27 | M21: =L21/(E21/60) -> 16.6737 | N21: =IFERROR(AVERAGEIF(Losses!$A:$A,$A21,Losses!$F:$F),0) -> 1.1453705 | O21: =IFERROR(_xlfn.MAXIFS(Losses!$F:$F,Losses!$A:$A,$A21),0) -> 18.922001 | P21: =SUMIFS(Timeline!$F:$F,Timeline!$A:$A,$A21,Timeline!$G:$G,P$3)/$E21 -> 0.29449663 | Q21: =SUMIFS(Timeline!$F:$F,Timeline!$A:$A,$A21,Timeline!$G:$G,Q$3)/$E21 -> 0.17427103 | R21: =SUMIFS(Timeline!$F:$F,Timeline!$A:$A,$A21,Timeline!$G:$G,R$3)/$E21 -> 0.3042127 | S21: =SUMIFS(Timeline!$F:$F,Timeline!$A:$A,$A21,Timeline!$G:$G,S$3)/$E21 -> 0.22701964 | T21: =SUMIFS(Timeline!$F:$F,Timeline!$A:$A,$A21,Timeline!$G:$G,T$3)/$E21 -> 0 | U21: =SUM(P21:T21) -> 1 | V21: 1665 | W21: 1 | X21: Yes
A24: Summary by tracker build
A25: Group | C25: Rounds | D25: Play time (min) | E25: Hits / min | F25: Losses / min | G25: Mean reacquire (s) | H25: % Tracking, 2+ boxes fused | I25: % Tracking, one box | J25: % Searching (lost) | K25: % Tracker alert | L25: % Paused / calibrating
A26: Before fix | C26: =COUNTIF($F$5:$F$21,"Before fix") -> 5 | D26: =SUMIF($F$5:$F$21,"Before fix",$E$5:$E$21)/60 -> 5.46155 | E26: =(SUMIF($F$5:$F$21,"Before fix",$I$5:$I$21)+SUMIF($F$5:$F$21,"Before fix",$J$5:$J$21))/D26 -> 1.6478838 | F26: =SUMIF($F$5:$F$21,"Before fix",$L$5:$L$21)/D26 -> 12.084482 | G26: =IFERROR(AVERAGEIF(Losses!$E:$E,"Before fix",Losses!$F:$F),0) -> 0.4975758 | H26: =SUMPRODUCT(($F$5:$F$21="Before fix")*$E$5:$E$21*P$5:P$21)/(D26*60) -> 0.72710433 | I26: =SUMPRODUCT(($F$5:$F$21="Before fix")*$E$5:$E$21*Q$5:Q$21)/(D26*60) -> 0.1289347 | J26: =SUMPRODUCT(($F$5:$F$21="Before fix")*$E$5:$E$21*R$5:R$21)/(D26*60) -> 0.11534577 | K26: =SUMPRODUCT(($F$5:$F$21="Before fix")*$E$5:$E$21*S$5:S$21)/(D26*60) -> 0.010988942 | L26: =SUMPRODUCT(($F$5:$F$21="Before fix")*$E$5:$E$21*T$5:T$21)/(D26*60) -> 0.017626255
A27: After fix | C27: =COUNTIF($F$5:$F$21,"After fix") -> 12 | D27: =SUMIF($F$5:$F$21,"After fix",$E$5:$E$21)/60 -> 17.842083 | E27: =(SUMIF($F$5:$F$21,"After fix",$I$5:$I$21)+SUMIF($F$5:$F$21,"After fix",$J$5:$J$21))/D27 -> 4.7640177 | F27: =SUMIF($F$5:$F$21,"After fix",$L$5:$L$21)/D27 -> 14.404148 | G27: =IFERROR(AVERAGEIF(Losses!$E:$E,"After fix",Losses!$F:$F),0) -> 0.77760318 | H27: =SUMPRODUCT(($F$5:$F$21="After fix")*$E$5:$E$21*P$5:P$21)/(D27*60) -> 0.33734288 | I27: =SUMPRODUCT(($F$5:$F$21="After fix")*$E$5:$E$21*Q$5:Q$21)/(D27*60) -> 0.15338921 | J27: =SUMPRODUCT(($F$5:$F$21="After fix")*$E$5:$E$21*R$5:R$21)/(D27*60) -> 0.20031014 | K27: =SUMPRODUCT(($F$5:$F$21="After fix")*$E$5:$E$21*S$5:S$21)/(D27*60) -> 0.080005609 | L27: =SUMPRODUCT(($F$5:$F$21="After fix")*$E$5:$E$21*T$5:T$21)/(D27*60) -> 0.22895215
A28: All rounds | C28: =COUNTIF($F$5:$F$21,"*") -> 17 | D28: =SUMIF($F$5:$F$21,"*",$E$5:$E$21)/60 -> 23.303633 | E28: =(SUMIF($F$5:$F$21,"*",$I$5:$I$21)+SUMIF($F$5:$F$21,"*",$J$5:$J$21))/D28 -> 4.0337058 | F28: =SUMIF($F$5:$F$21,"*",$L$5:$L$21)/D28 -> 13.8605 | G28: =IFERROR(AVERAGEIF(Losses!$E:$E,"*",Losses!$F:$F),0) -> 0.72038396 | H28: =SUMPRODUCT(($F$5:$F$21=$F$5:$F$21)*$E$5:$E$21*P$5:P$21)/(D28*60) -> 0.42868923 | I28: =SUMPRODUCT(($F$5:$F$21=$F$5:$F$21)*$E$5:$E$21*Q$5:Q$21)/(D28*60) -> 0.14765794 | J28: =SUMPRODUCT(($F$5:$F$21=$F$5:$F$21)*$E$5:$E$21*R$5:R$21)/(D28*60) -> 0.18039749 | K28: =SUMPRODUCT(($F$5:$F$21=$F$5:$F$21)*$E$5:$E$21*S$5:S$21)/(D28*60) -> 0.063830536 | L28: =SUMPRODUCT(($F$5:$F$21=$F$5:$F$21)*$E$5:$E$21*T$5:T$21)/(D28*60) -> 0.17942481

Sheet Timeline
A1: Tracker status timeline per round
A2: Each row = one stretch of constant tracker status, as logged by software/game/swarm_tracking.py. End = start of the next row (or round end).
A4: Round | B4: Start | C4: End | D4: Start in round (s) | E4: End in round (s) | F4: Duration (s) | G4: Category | H4: Tracker status text | I4: Box 0 reading | J4: Box 1 reading | K4: Box 2 reading | L4: Box 0 state | M4: Box 1 state | N4: Box 2 state | O4: Day
A5: 1 | B5: 46300.111 | C5: =IF(A6=A5,B6,INDEX(Rounds!$D:$D,MATCH(A5,Rounds!$A:$A,0))) -> 46300.111 | D5: =(B5-INDEX(Rounds!$C:$C,MATCH(A5,Rounds!$A:$A,0)))*86400 -> 0 | E5: =(C5-INDEX(Rounds!$C:$C,MATCH(A5,Rounds!$A:$A,0)))*86400 -> 0 | F5: =(C5-B5)*86400 -> 0 | G5: Waiting / other | L5: =IF(ISNUMBER(SEARCH(" m",I5)),"Range",IF(I5="offline","Offline",IF(I5="","Unknown","No echo / error"))) -> Unknown | M5: =IF(ISNUMBER(SEARCH(" m",J5)),"Range",IF(J5="offline","Offline",IF(J5="","Unknown","No echo / error"))) -> Unknown | N5: =IF(ISNUMBER(SEARCH(" m",K5)),"Range",IF(K5="offline","Offline",IF(K5="","Unknown","No echo / error"))) -> Unknown | O5: =TEXT(B5,"yyyy-mm-dd") -> 2026-10-05
A6: 1 | B6: 46300.111 | C6: =IF(A7=A6,B7,INDEX(Rounds!$D:$D,MATCH(A6,Rounds!$A:$A,0))) -> 46300.111 | D6: =(B6-INDEX(Rounds!$C:$C,MATCH(A6,Rounds!$A:$A,0)))*86400 -> 0 | E6: =(C6-INDEX(Rounds!$C:$C,MATCH(A6,Rounds!$A:$A,0)))*86400 -> 0 | F6: =(C6-B6)*86400 -> 0 | G6: Waiting / other | L6: =IF(ISNUMBER(SEARCH(" m",I6)),"Range",IF(I6="offline","Offline",IF(I6="","Unknown","No echo / error"))) -> Unknown | M6: =IF(ISNUMBER(SEARCH(" m",J6)),"Range",IF(J6="offline","Offline",IF(J6="","Unknown","No echo / error"))) -> Unknown | N6: =IF(ISNUMBER(SEARCH(" m",K6)),"Range",IF(K6="offline","Offline",IF(K6="","Unknown","No echo / error"))) -> Unknown | O6: =TEXT(B6,"yyyy-mm-dd") -> 2026-10-05
A7: 1 | B7: 46300.111 | C7: =IF(A8=A7,B8,INDEX(Rounds!$D:$D,MATCH(A7,Rounds!$A:$A,0))) -> 46300.111 | D7: =(B7-INDEX(Rounds!$C:$C,MATCH(A7,Rounds!$A:$A,0)))*86400 -> 0 | E7: =(C7-INDEX(Rounds!$C:$C,MATCH(A7,Rounds!$A:$A,0)))*86400 -> 0.54699965 | F7: =(C7-B7)*86400 -> 0.54699965 | G7: Searching (lost) | H7: Searching — 0:sweep, 1:sweep, 2:sweep | I7: offline | J7: 1.01 m | K7: 1.13 m | L7: =IF(ISNUMBER(SEARCH(" m",I7)),"Range",IF(I7="offline","Offline",IF(I7="","Unknown","No echo / error"))) -> Offline | M7: =IF(ISNUMBER(SEARCH(" m",J7)),"Range",IF(J7="offline","Offline",IF(J7="","Unknown","No echo / error"))) -> Range | N7: =IF(ISNUMBER(SEARCH(" m",K7)),"Range",IF(K7="offline","Offline",IF(K7="","Unknown","No echo / error"))) -> Range | O7: =TEXT(B7,"yyyy-mm-dd") -> 2026-10-05
A8: 1 | B8: 46300.111 | C8: =IF(A9=A8,B9,INDEX(Rounds!$D:$D,MATCH(A8,Rounds!$A:$A,0))) -> 46300.111 | D8: =(B8-INDEX(Rounds!$C:$C,MATCH(A8,Rounds!$A:$A,0)))*86400 -> 0.54699965 | E8: =(C8-INDEX(Rounds!$C:$C,MATCH(A8,Rounds!$A:$A,0)))*86400 -> 0.96500055 | F8: =(C8-B8)*86400 -> 0.4180009 | G8: Tracking, one box | H8: Tracking player (one box) | I8: offline | J8: timeout | K8: 0.63 m | L8: =IF(ISNUMBER(SEARCH(" m",I8)),"Range",IF(I8="offline","Offline",IF(I8="","Unknown","No echo / error"))) -> Offline | M8: =IF(ISNUMBER(SEARCH(" m",J8)),"Range",IF(J8="offline","Offline",IF(J8="","Unknown","No echo / error"))) -> No echo / error | N8: =IF(ISNUMBER(SEARCH(" m",K8)),"Range",IF(K8="offline","Offline",IF(K8="","Unknown","No echo / error"))) -> Range | O8: =TEXT(B8,"yyyy-mm-dd") -> 2026-10-05
A9: 1 | B9: 46300.111 | C9: =IF(A10=A9,B10,INDEX(Rounds!$D:$D,MATCH(A9,Rounds!$A:$A,0))) -> 46300.111 | D9: =(B9-INDEX(Rounds!$C:$C,MATCH(A9,Rounds!$A:$A,0)))*86400 -> 0.96500055 | E9: =(C9-INDEX(Rounds!$C:$C,MATCH(A9,Rounds!$A:$A,0)))*86400 -> 1.4640002 | F9: =(C9-B9)*86400 -> 0.49899963 | G9: Tracking, 2+ boxes fused | H9: Tracking player | I9: offline | J9: 0.68 m | K9: timeout | L9: =IF(ISNUMBER(SEARCH(" m",I9)),"Range",IF(I9="offline","Offline",IF(I9="","Unknown","No echo / error"))) -> Offline | M9: =IF(ISNUMBER(SEARCH(" m",J9)),"Range",IF(J9="offline","Offline",IF(J9="","Unknown","No echo / error"))) -> Range | N9: =IF(ISNUMBER(SEARCH(" m",K9)),"Range",IF(K9="offline","Offline",IF(K9="","Unknown","No echo / error"))) -> No echo / error | O9: =TEXT(B9,"yyyy-mm-dd") -> 2026-10-05
A10: 1 | B10: 46300.111 | C10: =IF(A11=A10,B11,INDEX(Rounds!$D:$D,MATCH(A10,Rounds!$A:$A,0))) -> 46300.111 | D10: =(B10-INDEX(Rounds!$C:$C,MATCH(A10,Rounds!$A:$A,0)))*86400 -> 1.4640002 | E10: =(C10-INDEX(Rounds!$C:$C,MATCH(A10,Rounds!$A:$A,0)))*86400 -> 1.4800004 | F10: =(C10-B10)*86400 -> 0.016000214 | G10: Searching (lost) | H10: Searching — 0:search, 1:search, 2:search | I10: offline | J10: 0.69 m ? | K10: timeout | L10: =IF(ISNUMBER(SEARCH(" m",I10)),"Range",IF(I10="offline","Offline",IF(I10="","Unknown","No echo / error"))) -> Offline | M10: =IF(ISNUMBER(SEARCH(" m",J10)),"Range",IF(J10="offline","Offline",IF(J10="","Unknown","No echo / error"))) -> Range | N10: =IF(ISNUMBER(SEARCH(" m",K10)),"Range",IF(K10="offline","Offline",IF(K10="","Unknown","No echo / error"))) -> No echo / error | O10: =TEXT(B10,"yyyy-mm-dd") -> 2026-10-05
A11: 1 | B11: 46300.111 | C11: =IF(A12=A11,B12,INDEX(Rounds!$D:$D,MATCH(A11,Rounds!$A:$A,0))) -> 46300.111 | D11: =(B11-INDEX(Rounds!$C:$C,MATCH(A11,Rounds!$A:$A,0)))*86400 -> 1.4800004 | E11: =(C11-INDEX(Rounds!$C:$C,MATCH(A11,Rounds!$A:$A,0)))*86400 -> 2.2999995 | F11: =(C11-B11)*86400 -> 0.81999907 | G11: Tracking, one box | H11: Tracking player (one box) | I11: offline | J11: 0.71 m | K11: timeout | L11: =IF(ISNUMBER(SEARCH(" m",I11)),"Range",IF(I11="offline","Offline",IF(I11="","Unknown","No echo / error"))) -> Offline | M11: =IF(ISNUMBER(SEARCH(" m",J11)),"Range",IF(J11="offline","Offline",IF(J11="","Unknown","No echo / error"))) -> Range | N11: =IF(ISNUMBER(SEARCH(" m",K11)),"Range",IF(K11="offline","Offline",IF(K11="","Unknown","No echo / error"))) -> No echo / error | O11: =TEXT(B11,"yyyy-mm-dd") -> 2026-10-05
A12: 1 | B12: 46300.111 | C12: =IF(A13=A12,B13,INDEX(Rounds!$D:$D,MATCH(A12,Rounds!$A:$A,0))) -> 46300.111 | D12: =(B12-INDEX(Rounds!$C:$C,MATCH(A12,Rounds!$A:$A,0)))*86400 -> 2.2999995 | E12: =(C12-INDEX(Rounds!$C:$C,MATCH(A12,Rounds!$A:$A,0)))*86400 -> 2.9439999 | F12: =(C12-B12)*86400 -> 0.64400048 | G12: Searching (lost) | H12: Searching — 0:search, 1:search, 2:search | I12: offline | J12: no range reply | K12: timeout | L12: =IF(ISNUMBER(SEARCH(" m",I12)),"Range",IF(I12="offline","Offline",IF(I12="","Unknown","No echo / error"))) -> Offline | M12: =IF(ISNUMBER(SEARCH(" m",J12)),"Range",IF(J12="offline","Offline",IF(J12="","Unknown","No echo / error"))) -> No echo / error | N12: =IF(ISNUMBER(SEARCH(" m",K12)),"Range",IF(K12="offline","Offline",IF(K12="","Unknown","No echo / error"))) -> No echo / error | O12: =TEXT(B12,"yyyy-mm-dd") -> 2026-10-05
A13: 1 | B13: 46300.111 | C13: =IF(A14=A13,B14,INDEX(Rounds!$D:$D,MATCH(A13,Rounds!$A:$A,0))) -> 46300.111 | D13: =(B13-INDEX(Rounds!$C:$C,MATCH(A13,Rounds!$A:$A,0)))*86400 -> 2.9439999 | E13: =(C13-INDEX(Rounds!$C:$C,MATCH(A13,Rounds!$A:$A,0)))*86400 -> 3.4780005 | F13: =(C13-B13)*86400 -> 0.53400057 | G13: Tracking, one box | H13: Tracking player (one box) | I13: offline | J13: 0.65 m | K13: timeout | L13: =IF(ISNUMBER(SEARCH(" m",I13)),"Range",IF(I13="offline","Offline",IF(I13="","Unknown","No echo / error"))) -> Offline | M13: =IF(ISNUMBER(SEARCH(" m",J13)),"Range",IF(J13="offline","Offline",IF(J13="","Unknown","No echo / error"))) -> Range | N13: =IF(ISNUMBER(SEARCH(" m",K13)),"Range",IF(K13="offline","Offline",IF(K13="","Unknown","No echo / error"))) -> No echo / error | O13: =TEXT(B13,"yyyy-mm-dd") -> 2026-10-05
A14: 1 | B14: 46300.111 | C14: =IF(A15=A14,B15,INDEX(Rounds!$D:$D,MATCH(A14,Rounds!$A:$A,0))) -> 46300.111 | D14: =(B14-INDEX(Rounds!$C:$C,MATCH(A14,Rounds!$A:$A,0)))*86400 -> 3.4780005 | E14: =(C14-INDEX(Rounds!$C:$C,MATCH(A14,Rounds!$A:$A,0)))*86400 -> 6.0240005 | F14: =(C14-B14)*86400 -> 2.5459999 | G14: Tracking, 2+ boxes fused | H14: Tracking player | I14: offline | J14: 0.66 m | K14: 0.86 m | L14: =IF(ISNUMBER(SEARCH(" m",I14)),"Range",IF(I14="offline","Offline",IF(I14="","Unknown","No echo / error"))) -> Offline | M14: =IF(ISNUMBER(SEARCH(" m",J14)),"Range",IF(J14="offline","Offline",IF(J14="","Unknown","No echo / error"))) -> Range | N14: =IF(ISNUMBER(SEARCH(" m",K14)),"Range",IF(K14="offline","Offline",IF(K14="","Unknown","No echo / error"))) -> Range | O14: =TEXT(B14,"yyyy-mm-dd") -> 2026-10-05
A15: 1 | B15: 46300.111 | C15: =IF(A16=A15,B16,INDEX(Rounds!$D:$D,MATCH(A15,Rounds!$A:$A,0))) -> 46300.111 | D15: =(B15-INDEX(Rounds!$C:$C,MATCH(A15,Rounds!$A:$A,0)))*86400 -> 6.0240005 | E15: =(C15-INDEX(Rounds!$C:$C,MATCH(A15,Rounds!$A:$A,0)))*86400 -> 6.0890002 | F15: =(C15-B15)*86400 -> 0.064999773 | G15: Searching (lost) | H15: Searching — 0:search, 1:search, 2:search | I15: offline | J15: 0.56 m ? | K15: 1.05 m ? | L15: =IF(ISNUMBER(SEARCH(" m",I15)),"Range",IF(I15="offline","Offline",IF(I15="","Unknown","No echo / error"))) -> Offline | M15: =IF(ISNUMBER(SEARCH(" m",J15)),"Range",IF(J15="offline","Offline",IF(J15="","Unknown","No echo / error"))) -> Range | N15: =IF(ISNUMBER(SEARCH(" m",K15)),"Range",IF(K15="offline","Offline",IF(K15="","Unknown","No echo / error"))) -> Range | O15: =TEXT(B15,"yyyy-mm-dd") -> 2026-10-05
A16: 1 | B16: 46300.111 | C16: =IF(A17=A16,B17,INDEX(Rounds!$D:$D,MATCH(A16,Rounds!$A:$A,0))) -> 46300.111 | D16: =(B16-INDEX(Rounds!$C:$C,MATCH(A16,Rounds!$A:$A,0)))*86400 -> 6.0890002 | E16: =(C16-INDEX(Rounds!$C:$C,MATCH(A16,Rounds!$A:$A,0)))*86400 -> 6.2010005 | F16: =(C16-B16)*86400 -> 0.11200025 | G16: Tracking, one box | H16: Tracking player (one box) | I16: offline | J16: 0.59 m | K16: 1.05 m ? | L16: =IF(ISNUMBER(SEARCH(" m",I16)),"Range",IF(I16="offline","Offline",IF(I16="","Unknown","No echo / error"))) -> Offline | M16: =IF(ISNUMBER(SEARCH(" m",J16)),"Range",IF(J16="offline","Offline",IF(J16="","Unknown","No echo / error"))) -> Range | N16: =IF(ISNUMBER(SEARCH(" m",K16)),"Range",IF(K16="offline","Offline",IF(K16="","Unknown","No echo / error"))) -> Range | O16: =TEXT(B16,"yyyy-mm-dd") -> 2026-10-05
A17: 1 | B17: 46300.111 | C17: =IF(A18=A17,B18,INDEX(Rounds!$D:$D,MATCH(A17,Rounds!$A:$A,0))) -> 46300.111 | D17: =(B17-INDEX(Rounds!$C:$C,MATCH(A17,Rounds!$A:$A,0)))*86400 -> 6.2010005 | E17: =(C17-INDEX(Rounds!$C:$C,MATCH(A17,Rounds!$A:$A,0)))*86400 -> 9.275 | F17: =(C17-B17)*86400 -> 3.0739995 | G17: Tracking, 2+ boxes fused | H17: Tracking player | I17: offline | J17: 0.59 m | K17: 1.05 m | L17: =IF(ISNUMBER(SEARCH(" m",I17)),"Range",IF(I17="offline","Offline",IF(I17="","Unknown","No echo / error"))) -> Offline | M17: =IF(ISNUMBER(SEARCH(" m",J17)),"Range",IF(J17="offline","Offline",IF(J17="","Unknown","No echo / error"))) -> Range | N17: =IF(ISNUMBER(SEARCH(" m",K17)),"Range",IF(K17="offline","Offline",IF(K17="","Unknown","No echo / error"))) -> Range | O17: =TEXT(B17,"yyyy-mm-dd") -> 2026-10-05
A18: 1 | B18: 46300.111 | C18: =IF(A19=A18,B19,INDEX(Rounds!$D:$D,MATCH(A18,Rounds!$A:$A,0))) -> 46300.111 | D18: =(B18-INDEX(Rounds!$C:$C,MATCH(A18,Rounds!$A:$A,0)))*86400 -> 9.275 | E18: =(C18-INDEX(Rounds!$C:$C,MATCH(A18,Rounds!$A:$A,0)))*86400 -> 9.6450002 | F18: =(C18-B18)*86400 -> 0.37000026 | G18: Tracking, one box | H18: Tracking player (one box) | I18: offline | J18: 0.72 m | K18: invalid | L18: =IF(ISNUMBER(SEARCH(" m",I18)),"Range",IF(I18="offline","Offline",IF(I18="","Unknown","No echo / error"))) -> Offline | M18: =IF(ISNUMBER(SEARCH(" m",J18)),"Range",IF(J18="offline","Offline",IF(J18="","Unknown","No echo / error"))) -> Range | N18: =IF(ISNUMBER(SEARCH(" m",K18)),"Range",IF(K18="offline","Offline",IF(K18="","Unknown","No echo / error"))) -> No echo / error | O18: =TEXT(B18,"yyyy-mm-dd") -> 2026-10-05
... A1151: 17 | B1151: 46301.527 | C1151: =IF(A1152=A1151,B1152,INDEX(Rounds!$D:$D,MATCH(A1151,Rounds!$A:$A,0))) -> 46301.527 | D1151: =(B1151-INDEX(Rounds!$C:$C,MATCH(A1151,Rounds!$A:$A,0)))*86400 -> 97.159001 | E1151: =(C1151-INDEX(Rounds!$C:$C,MATCH(A1151,Rounds!$A:$A,0)))*86400 -> 97.159001 | F1151: =(C1151-B1151)*86400 -> 0 | G1151: Paused / calibrating | H1151: Tracking player | I1151: 0.86 m | J1151: 3.45 m | K1151: 1.03 m | L1151: =IF(ISNUMBER(SEARCH(" m",I1151)),"Range",IF(I1151="offline","Offline",IF(I1151="","Unknown","No echo / error"))) -> Range | M1151: =IF(ISNUMBER(SEARCH(" m",J1151)),"Range",IF(J1151="offline","Offline",IF(J1151="","Unknown","No echo / error"))) -> Range | N1151: =IF(ISNUMBER(SEARCH(" m",K1151)),"Range",IF(K1151="offline","Offline",IF(K1151="","Unknown","No echo / error"))) -> Range | O1151: =TEXT(B1151,"yyyy-mm-dd") -> 2026-10-06

Sheet Losses
A1: Tracker losses and reacquisition (field)
A2: A loss = tracker state 'track' -> 'find' while not parked; it ends at the next 'track'. Same rule as results/report/reacquire_report.py.
A4: Round | B4: Lost at | C4: Reacquired at | D4: Lost at (s in round) | E4: Tracker build | F4: Reacquire time (s) | G4: Longer than grace? | I4: Reacquire-time histogram
A5: 1 | B5: 46300.111 | C5: 46300.111 | D5: =(B5-INDEX(Rounds!$C:$C,MATCH(A5,Rounds!$A:$A,0)))*86400 -> 1.4640002 | E5: =INDEX(Rounds!$F:$F,MATCH(A5,Rounds!$A:$A,0)) -> Before fix | F5: =(C5-B5)*86400 -> 0.016000214 | G5: =IF(F5*1000>Constants!$B$12,"Yes","No") -> No | I5: Bin | J5: From (s) | K5: To (s) | L5: Before fix | M5: After fix | N5: Before % | O5: After %
A6: 1 | B6: 46300.111 | C6: 46300.111 | D6: =(B6-INDEX(Rounds!$C:$C,MATCH(A6,Rounds!$A:$A,0)))*86400 -> 2.2999995 | E6: =INDEX(Rounds!$F:$F,MATCH(A6,Rounds!$A:$A,0)) -> Before fix | F6: =(C6-B6)*86400 -> 0.64400048 | G6: =IF(F6*1000>Constants!$B$12,"Yes","No") -> No | I6: < 0.25 s | J6: 0 | K6: 0.25 | L6: =COUNTIFS($E$5:$E$327,"Before fix",$F$5:$F$327,">="&$J6,$F$5:$F$327,"<"&$K6) -> 32 | M6: =COUNTIFS($E$5:$E$327,"After fix",$F$5:$F$327,">="&$J6,$F$5:$F$327,"<"&$K6) -> 104 | N6: =L6/SUM(L$6:L$11) -> 0.48484848 | O6: =M6/SUM(M$6:M$11) -> 0.40466926
A7: 1 | B7: 46300.111 | C7: 46300.111 | D7: =(B7-INDEX(Rounds!$C:$C,MATCH(A7,Rounds!$A:$A,0)))*86400 -> 6.0240005 | E7: =INDEX(Rounds!$F:$F,MATCH(A7,Rounds!$A:$A,0)) -> Before fix | F7: =(C7-B7)*86400 -> 0.064999773 | G7: =IF(F7*1000>Constants!$B$12,"Yes","No") -> No | I7: 0.25-0.5 s | J7: 0.25 | K7: 0.5 | L7: =COUNTIFS($E$5:$E$327,"Before fix",$F$5:$F$327,">="&$J7,$F$5:$F$327,"<"&$K7) -> 6 | M7: =COUNTIFS($E$5:$E$327,"After fix",$F$5:$F$327,">="&$J7,$F$5:$F$327,"<"&$K7) -> 46 | N7: =L7/SUM(L$6:L$11) -> 0.090909091 | O7: =M7/SUM(M$6:M$11) -> 0.17898833
A8: 1 | B8: 46300.111 | C8: 46300.111 | D8: =(B8-INDEX(Rounds!$C:$C,MATCH(A8,Rounds!$A:$A,0)))*86400 -> 13.391001 | E8: =INDEX(Rounds!$F:$F,MATCH(A8,Rounds!$A:$A,0)) -> Before fix | F8: =(C8-B8)*86400 -> 0.23999882 | G8: =IF(F8*1000>Constants!$B$12,"Yes","No") -> No | I8: 0.5-1 s | J8: 0.5 | K8: 1 | L8: =COUNTIFS($E$5:$E$327,"Before fix",$F$5:$F$327,">="&$J8,$F$5:$F$327,"<"&$K8) -> 19 | M8: =COUNTIFS($E$5:$E$327,"After fix",$F$5:$F$327,">="&$J8,$F$5:$F$327,"<"&$K8) -> 55 | N8: =L8/SUM(L$6:L$11) -> 0.28787879 | O8: =M8/SUM(M$6:M$11) -> 0.21400778
A9: 1 | B9: 46300.111 | C9: 46300.111 | D9: =(B9-INDEX(Rounds!$C:$C,MATCH(A9,Rounds!$A:$A,0)))*86400 -> 28.688 | E9: =INDEX(Rounds!$F:$F,MATCH(A9,Rounds!$A:$A,0)) -> Before fix | F9: =(C9-B9)*86400 -> 0.06300006 | G9: =IF(F9*1000>Constants!$B$12,"Yes","No") -> No | I9: 1-2 s | J9: 1 | K9: 2 | L9: =COUNTIFS($E$5:$E$327,"Before fix",$F$5:$F$327,">="&$J9,$F$5:$F$327,"<"&$K9) -> 8 | M9: =COUNTIFS($E$5:$E$327,"After fix",$F$5:$F$327,">="&$J9,$F$5:$F$327,"<"&$K9) -> 36 | N9: =L9/SUM(L$6:L$11) -> 0.12121212 | O9: =M9/SUM(M$6:M$11) -> 0.14007782
A10: 1 | B10: 46300.112 | C10: 46300.112 | D10: =(B10-INDEX(Rounds!$C:$C,MATCH(A10,Rounds!$A:$A,0)))*86400 -> 33.613 | E10: =INDEX(Rounds!$F:$F,MATCH(A10,Rounds!$A:$A,0)) -> Before fix | F10: =(C10-B10)*86400 -> 1.1399996 | G10: =IF(F10*1000>Constants!$B$12,"Yes","No") -> Yes | I10: 2-3 s | J10: 2 | K10: 3 | L10: =COUNTIFS($E$5:$E$327,"Before fix",$F$5:$F$327,">="&$J10,$F$5:$F$327,"<"&$K10) -> 1 | M10: =COUNTIFS($E$5:$E$327,"After fix",$F$5:$F$327,">="&$J10,$F$5:$F$327,"<"&$K10) -> 6 | N10: =L10/SUM(L$6:L$11) -> 0.015151515 | O10: =M10/SUM(M$6:M$11) -> 0.023346304
A11: 1 | B11: 46300.112 | C11: 46300.112 | D11: =(B11-INDEX(Rounds!$C:$C,MATCH(A11,Rounds!$A:$A,0)))*86400 -> 47.101001 | E11: =INDEX(Rounds!$F:$F,MATCH(A11,Rounds!$A:$A,0)) -> Before fix | F11: =(C11-B11)*86400 -> 0.016999756 | G11: =IF(F11*1000>Constants!$B$12,"Yes","No") -> No | I11: >= 3 s | J11: 3 | K11: 9999 | L11: =COUNTIFS($E$5:$E$327,"Before fix",$F$5:$F$327,">="&$J11,$F$5:$F$327,"<"&$K11) -> 0 | M11: =COUNTIFS($E$5:$E$327,"After fix",$F$5:$F$327,">="&$J11,$F$5:$F$327,"<"&$K11) -> 10 | N11: =L11/SUM(L$6:L$11) -> 0 | O11: =M11/SUM(M$6:M$11) -> 0.038910506
A12: 1 | B12: 46300.112 | C12: 46300.112 | D12: =(B12-INDEX(Rounds!$C:$C,MATCH(A12,Rounds!$A:$A,0)))*86400 -> 49.392 | E12: =INDEX(Rounds!$F:$F,MATCH(A12,Rounds!$A:$A,0)) -> Before fix | F12: =(C12-B12)*86400 -> 0.080000446 | G12: =IF(F12*1000>Constants!$B$12,"Yes","No") -> No | I12: Total | L12: =SUM(L6:L11) -> 66 | M12: =SUM(M6:M11) -> 257
A13: 1 | B13: 46300.112 | C13: 46300.112 | D13: =(B13-INDEX(Rounds!$C:$C,MATCH(A13,Rounds!$A:$A,0)))*86400 -> 50.754 | E13: =INDEX(Rounds!$F:$F,MATCH(A13,Rounds!$A:$A,0)) -> Before fix | F13: =(C13-B13)*86400 -> 0.72100041 | G13: =IF(F13*1000>Constants!$B$12,"Yes","No") -> No
A14: 1 | B14: 46300.112 | C14: 46300.112 | D14: =(B14-INDEX(Rounds!$C:$C,MATCH(A14,Rounds!$A:$A,0)))*86400 -> 59.252 | E14: =INDEX(Rounds!$F:$F,MATCH(A14,Rounds!$A:$A,0)) -> Before fix | F14: =(C14-B14)*86400 -> 1.804001 | G14: =IF(F14*1000>Constants!$B$12,"Yes","No") -> Yes | I14: Median reacquire (s) | L14: {=MEDIAN(IF($E$5:$E$327="Before fix",$F$5:$F$327))} -> 0.2825001 | M14: {=MEDIAN(IF($E$5:$E$327="After fix",$F$5:$F$327))} -> 0.38700001
A15: 2 | B15: 46300.113 | C15: 46300.113 | D15: =(B15-INDEX(Rounds!$C:$C,MATCH(A15,Rounds!$A:$A,0)))*86400 -> 1.1549996 | E15: =INDEX(Rounds!$F:$F,MATCH(A15,Rounds!$A:$A,0)) -> Before fix | F15: =(C15-B15)*86400 -> 0.53100006 | G15: =IF(F15*1000>Constants!$B$12,"Yes","No") -> No | I15: Share longer than grace (1 s) | L15: =COUNTIFS($E$5:$E$327,"Before fix",$G$5:$G$327,"Yes")/L12 -> 0.13636364 | M15: =COUNTIFS($E$5:$E$327,"After fix",$G$5:$G$327,"Yes")/M12 -> 0.20233463
A16: 2 | B16: 46300.113 | C16: 46300.113 | D16: =(B16-INDEX(Rounds!$C:$C,MATCH(A16,Rounds!$A:$A,0)))*86400 -> 3.6519994 | E16: =INDEX(Rounds!$F:$F,MATCH(A16,Rounds!$A:$A,0)) -> Before fix | F16: =(C16-B16)*86400 -> 0.016000214 | G16: =IF(F16*1000>Constants!$B$12,"Yes","No") -> No
A17: 2 | B17: 46300.113 | C17: 46300.113 | D17: =(B17-INDEX(Rounds!$C:$C,MATCH(A17,Rounds!$A:$A,0)))*86400 -> 22.664 | E17: =INDEX(Rounds!$F:$F,MATCH(A17,Rounds!$A:$A,0)) -> Before fix | F17: =(C17-B17)*86400 -> 0.81799999 | G17: =IF(F17*1000>Constants!$B$12,"Yes","No") -> No
A18: 2 | B18: 46300.113 | C18: 46300.113 | D18: =(B18-INDEX(Rounds!$C:$C,MATCH(A18,Rounds!$A:$A,0)))*86400 -> 27.994999 | E18: =INDEX(Rounds!$F:$F,MATCH(A18,Rounds!$A:$A,0)) -> Before fix | F18: =(C18-B18)*86400 -> 0.92800115 | G18: =IF(F18*1000>Constants!$B$12,"Yes","No") -> No
A19: 2 | B19: 46300.113 | C19: 46300.113 | D19: =(B19-INDEX(Rounds!$C:$C,MATCH(A19,Rounds!$A:$A,0)))*86400 -> 30.078 | E19: =INDEX(Rounds!$F:$F,MATCH(A19,Rounds!$A:$A,0)) -> Before fix | F19: =(C19-B19)*86400 -> 0.032999971 | G19: =IF(F19*1000>Constants!$B$12,"Yes","No") -> No
A20: 2 | B20: 46300.113 | C20: 46300.113 | D20: =(B20-INDEX(Rounds!$C:$C,MATCH(A20,Rounds!$A:$A,0)))*86400 -> 30.703999 | E20: =INDEX(Rounds!$F:$F,MATCH(A20,Rounds!$A:$A,0)) -> Before fix | F20: =(C20-B20)*86400 -> 0.98300048 | G20: =IF(F20*1000>Constants!$B$12,"Yes","No") -> No
A21: 2 | B21: 46300.113 | C21: 46300.113 | D21: =(B21-INDEX(Rounds!$C:$C,MATCH(A21,Rounds!$A:$A,0)))*86400 -> 32.136999 | E21: =INDEX(Rounds!$F:$F,MATCH(A21,Rounds!$A:$A,0)) -> Before fix | F21: =(C21-B21)*86400 -> 0.56200032 | G21: =IF(F21*1000>Constants!$B$12,"Yes","No") -> No
A22: 2 | B22: 46300.113 | C22: 46300.113 | D22: =(B22-INDEX(Rounds!$C:$C,MATCH(A22,Rounds!$A:$A,0)))*86400 -> 33.743999 | E22: =INDEX(Rounds!$F:$F,MATCH(A22,Rounds!$A:$A,0)) -> Before fix | F22: =(C22-B22)*86400 -> 1.3380001 | G22: =IF(F22*1000>Constants!$B$12,"Yes","No") -> Yes
A23: 2 | B23: 46300.113 | C23: 46300.113 | D23: =(B23-INDEX(Rounds!$C:$C,MATCH(A23,Rounds!$A:$A,0)))*86400 -> 46.124999 | E23: =INDEX(Rounds!$F:$F,MATCH(A23,Rounds!$A:$A,0)) -> Before fix | F23: =(C23-B23)*86400 -> 0.75500056 | G23: =IF(F23*1000>Constants!$B$12,"Yes","No") -> No
A24: 2 | B24: 46300.113 | C24: 46300.113 | D24: =(B24-INDEX(Rounds!$C:$C,MATCH(A24,Rounds!$A:$A,0)))*86400 -> 49.66 | E24: =INDEX(Rounds!$F:$F,MATCH(A24,Rounds!$A:$A,0)) -> Before fix | F24: =(C24-B24)*86400 -> 0.87100023 | G24: =IF(F24*1000>Constants!$B$12,"Yes","No") -> No
A25: 2 | B25: 46300.113 | C25: 46300.113 | D25: =(B25-INDEX(Rounds!$C:$C,MATCH(A25,Rounds!$A:$A,0)))*86400 -> 51.461 | E25: =INDEX(Rounds!$F:$F,MATCH(A25,Rounds!$A:$A,0)) -> Before fix | F25: =(C25-B25)*86400 -> 0.079999817 | G25: =IF(F25*1000>Constants!$B$12,"Yes","No") -> No
A26: 2 | B26: 46300.113 | C26: 46300.114 | D26: =(B26-INDEX(Rounds!$C:$C,MATCH(A26,Rounds!$A:$A,0)))*86400 -> 55.768 | E26: =INDEX(Rounds!$F:$F,MATCH(A26,Rounds!$A:$A,0)) -> Before fix | F26: =(C26-B26)*86400 -> 1.529 | G26: =IF(F26*1000>Constants!$B$12,"Yes","No") -> Yes
A27: 3 | B27: 46300.114 | C27: 46300.114 | D27: =(B27-INDEX(Rounds!$C:$C,MATCH(A27,Rounds!$A:$A,0)))*86400 -> 5.7530001 | E27: =INDEX(Rounds!$F:$F,MATCH(A27,Rounds!$A:$A,0)) -> Before fix | F27: =(C27-B27)*86400 -> 0.078999646 | G27: =IF(F27*1000>Constants!$B$12,"Yes","No") -> No
... A327: 17 | B327: 46301.527 | C327: 46301.527 | D327: =(B327-INDEX(Rounds!$C:$C,MATCH(A327,Rounds!$A:$A,0)))*86400 -> 95.484 | E327: =INDEX(Rounds!$F:$F,MATCH(A327,Rounds!$A:$A,0)) -> After fix | F327: =(C327-B327)*86400 -> 0.28900027 | G327: =IF(F327*1000>Constants!$B$12,"Yes","No") -> No

Sheet Hits
A1: Every hit: was the cursor on the hole?
A2: Cursor = last 'Cursor moved' sample at or before the hit. Normalised distance <= 1 means inside the hole's contact ellipse (main.contact_hole).
A4: Round | B4: Time | C4: Time in round (s) | D4: Kind | E4: Hole | F4: Points | G4: Score after | H4: Level (logged) | I4: Layout on screen | J4: Cursor x (m) | K4: Cursor y (m) | L4: Hole x (m) | M4: Hole y (m) | N4: dx (m) | O4: dy (m) | P4: Normalised distance | Q4: Inside contact ellipse? | R4: Layout source | T4: Check | W4: Contact ellipse outline
A5: 1 | B5: 46300.111 | C5: =(B5-INDEX(Rounds!$C:$C,MATCH(A5,Rounds!$A:$A,0)))*86400 -> 11.250001 | D5: mole_hit | E5: 5 | F5: 100 | G5: 100 | H5: 1 | I5: 2-3-2 | J5: 0.5302 | K5: 1.6011 | L5: =INDEX(Constants!$D$18:$D$41,MATCH(I5&"#"&E5,Constants!$A$18:$A$41,0)) -> 0.5 | M5: =INDEX(Constants!$E$18:$E$41,MATCH(I5&"#"&E5,Constants!$A$18:$A$41,0)) -> 1.74 | N5: =J5-L5 -> 0.0302 | O5: =K5-M5 -> -0.1389 | P5: =SQRT((N5/Constants!$B$8)^2+(O5/Constants!$B$9)^2) -> 1.007471 | Q5: =IF(P5<=1.05,"Yes","No") -> Yes | R5: Inferred: level 1 before @b7874bc (all hits fit 2-3-2) | T5: Hits | U5: =COUNTA(D5:D98) -> 94 | W5: Angle (deg) | X5: dx (m) | Y5: dy (m)
A6: 1 | B6: 46300.112 | C6: =(B6-INDEX(Rounds!$C:$C,MATCH(A6,Rounds!$A:$A,0)))*86400 -> 34.817 | D6: mole_hit | E6: 3 | F6: 100 | G6: 200 | H6: 1 | I6: 2-3-2 | J6: 0.5945 | K6: 1.43 | L6: =INDEX(Constants!$D$18:$D$41,MATCH(I6&"#"&E6,Constants!$A$18:$A$41,0)) -> 0.75 | M6: =INDEX(Constants!$E$18:$E$41,MATCH(I6&"#"&E6,Constants!$A$18:$A$41,0)) -> 1.42 | N6: =J6-L6 -> -0.1555 | O6: =K6-M6 -> 0.01 | P6: =SQRT((N6/Constants!$B$8)^2+(O6/Constants!$B$9)^2) -> 0.90427476 | Q6: =IF(P6<=1.05,"Yes","No") -> Yes | R6: Inferred: level 1 before @b7874bc (all hits fit 2-3-2) | T6: Inside ellipse (<= 1.05) | U6: =COUNTIF(Q5:Q98,"Yes") -> 94 | W6: 0 | X6: =Constants!$B$8*COS(RADIANS(W6)) -> 0.1725 | Y6: =Constants!$B$9*SIN(RADIANS(W6)) -> 0
A7: 1 | B7: 46300.112 | C7: =(B7-INDEX(Rounds!$C:$C,MATCH(A7,Rounds!$A:$A,0)))*86400 -> 39.806 | D7: mole_hit | E7: 0 | F7: 100 | G7: 300 | H7: 1 | I7: 2-3-2 | J7: 0.5862 | K7: 1.2187 | L7: =INDEX(Constants!$D$18:$D$41,MATCH(I7&"#"&E7,Constants!$A$18:$A$41,0)) -> 0.5 | M7: =INDEX(Constants!$E$18:$E$41,MATCH(I7&"#"&E7,Constants!$A$18:$A$41,0)) -> 1.1 | N7: =J7-L7 -> 0.0862 | O7: =K7-M7 -> 0.1187 | P7: =SQRT((N7/Constants!$B$8)^2+(O7/Constants!$B$9)^2) -> 0.98416054 | Q7: =IF(P7<=1.05,"Yes","No") -> Yes | R7: Inferred: level 1 before @b7874bc (all hits fit 2-3-2) | T7: Share inside | U7: =U6/U5 -> 1 | W7: 10 | X7: =Constants!$B$8*COS(RADIANS(W7)) -> 0.16987934 | Y7: =Constants!$B$9*SIN(RADIANS(W7)) -> 0.024310745
A8: 1 | B8: 46300.112 | C8: =(B8-INDEX(Rounds!$C:$C,MATCH(A8,Rounds!$A:$A,0)))*86400 -> 51.556001 | D8: mole_hit | E8: 2 | F8: 100 | G8: 400 | H8: 2 | I8: 2-3-2 | J8: 0.4185 | K8: 1.3949 | L8: =INDEX(Constants!$D$18:$D$41,MATCH(I8&"#"&E8,Constants!$A$18:$A$41,0)) -> 0.25 | M8: =INDEX(Constants!$E$18:$E$41,MATCH(I8&"#"&E8,Constants!$A$18:$A$41,0)) -> 1.42 | N8: =J8-L8 -> 0.1685 | O8: =K8-M8 -> -0.0251 | P8: =SQRT((N8/Constants!$B$8)^2+(O8/Constants!$B$9)^2) -> 0.99312852 | Q8: =IF(P8<=1.05,"Yes","No") -> Yes | R8: Inferred: level 1 before @b7874bc (all hits fit 2-3-2) | T8: Median normalised distance | U8: =MEDIAN(P5:P98) -> 0.95360445 | W8: 20 | X8: =Constants!$B$8*COS(RADIANS(W8)) -> 0.16209698 | Y8: =Constants!$B$9*SIN(RADIANS(W8)) -> 0.04788282
A9: 2 | B9: 46300.113 | C9: =(B9-INDEX(Rounds!$C:$C,MATCH(A9,Rounds!$A:$A,0)))*86400 -> 31.798999 | D9: mole_hit | E9: 2 | F9: 100 | G9: 100 | H9: 1 | I9: 2-3-2 | J9: 0.3863 | K9: 1.4708 | L9: =INDEX(Constants!$D$18:$D$41,MATCH(I9&"#"&E9,Constants!$A$18:$A$41,0)) -> 0.25 | M9: =INDEX(Constants!$E$18:$E$41,MATCH(I9&"#"&E9,Constants!$A$18:$A$41,0)) -> 1.42 | N9: =J9-L9 -> 0.1363 | O9: =K9-M9 -> 0.0508 | P9: =SQRT((N9/Constants!$B$8)^2+(O9/Constants!$B$9)^2) -> 0.86947933 | Q9: =IF(P9<=1.05,"Yes","No") -> Yes | R9: Inferred: level 1 before @b7874bc (all hits fit 2-3-2) | T9: Largest normalised distance | U9: =MAX(P5:P98) -> 1.007471 | W9: 30 | X9: =Constants!$B$8*COS(RADIANS(W9)) -> 0.14938938 | Y9: =Constants!$B$9*SIN(RADIANS(W9)) -> 0.07
A10: 2 | B10: 46300.113 | C10: =(B10-INDEX(Rounds!$C:$C,MATCH(A10,Rounds!$A:$A,0)))*86400 -> 55.447 | D10: mole_hit | E10: 2 | F10: 100 | G10: 200 | H10: 1 | I10: 2-3-2 | J10: 0.3843 | K10: 1.3321 | L10: =INDEX(Constants!$D$18:$D$41,MATCH(I10&"#"&E10,Constants!$A$18:$A$41,0)) -> 0.25 | M10: =INDEX(Constants!$E$18:$E$41,MATCH(I10&"#"&E10,Constants!$A$18:$A$41,0)) -> 1.42 | N10: =J10-L10 -> 0.1343 | O10: =K10-M10 -> -0.0879 | P10: =SQRT((N10/Constants!$B$8)^2+(O10/Constants!$B$9)^2) -> 1.0001729 | Q10: =IF(P10<=1.05,"Yes","No") -> Yes | R10: Inferred: level 1 before @b7874bc (all hits fit 2-3-2) | W10: 40 | X10: =Constants!$B$8*COS(RADIANS(W10)) -> 0.13214267 | Y10: =Constants!$B$9*SIN(RADIANS(W10)) -> 0.089990265
A11: 3 | B11: 46300.114 | C11: =(B11-INDEX(Rounds!$C:$C,MATCH(A11,Rounds!$A:$A,0)))*86400 -> 45.229 | D11: mole_hit | E11: 3 | F11: 100 | G11: 100 | H11: 1 | I11: 2-3-2 | J11: 0.7554 | K11: 1.2868 | L11: =INDEX(Constants!$D$18:$D$41,MATCH(I11&"#"&E11,Constants!$A$18:$A$41,0)) -> 0.75 | M11: =INDEX(Constants!$E$18:$E$41,MATCH(I11&"#"&E11,Constants!$A$18:$A$41,0)) -> 1.42 | N11: =J11-L11 -> 0.0054 | O11: =K11-M11 -> -0.1332 | P11: =SQRT((N11/Constants!$B$8)^2+(O11/Constants!$B$9)^2) -> 0.95194343 | Q11: =IF(P11<=1.05,"Yes","No") -> Yes | R11: Inferred: level 1 before @b7874bc (all hits fit 2-3-2) | T11: Tolerance 1.05: the cursor is logged only when it moves, so the logged sample can be up to one frame older than the position the hit was judged on (the hit fires on the first frame inside the ellipse, so values sit near 1.0). | W11: 50 | X11: =Constants!$B$8*COS(RADIANS(W11)) -> 0.11088086 | Y11: =Constants!$B$9*SIN(RADIANS(W11)) -> 0.10724622
A12: 5 | B12: 46300.128 | C12: =(B12-INDEX(Rounds!$C:$C,MATCH(A12,Rounds!$A:$A,0)))*86400 -> 29.93 | D12: mole_hit | E12: 3 | F12: 100 | G12: 100 | H12: 1 | I12: 2-3-2 | J12: 0.5923 | K12: 1.3793 | L12: =INDEX(Constants!$D$18:$D$41,MATCH(I12&"#"&E12,Constants!$A$18:$A$41,0)) -> 0.75 | M12: =INDEX(Constants!$E$18:$E$41,MATCH(I12&"#"&E12,Constants!$A$18:$A$41,0)) -> 1.42 | N12: =J12-L12 -> -0.1577 | O12: =K12-M12 -> -0.0407 | P12: =SQRT((N12/Constants!$B$8)^2+(O12/Constants!$B$9)^2) -> 0.95931316 | Q12: =IF(P12<=1.05,"Yes","No") -> Yes | R12: Inferred: level 1 before @b7874bc (all hits fit 2-3-2) | W12: 60 | X12: =Constants!$B$8*COS(RADIANS(W12)) -> 0.08625 | Y12: =Constants!$B$9*SIN(RADIANS(W12)) -> 0.12124356
A13: 5 | B13: 46300.128 | C13: =(B13-INDEX(Rounds!$C:$C,MATCH(A13,Rounds!$A:$A,0)))*86400 -> 61.609 | D13: mole_hit | E13: 4 | F13: 100 | G13: 200 | H13: 1 | I13: 2-3-2 | J13: 1.0863 | K13: 1.4467 | L13: =INDEX(Constants!$D$18:$D$41,MATCH(I13&"#"&E13,Constants!$A$18:$A$41,0)) -> 1.25 | M13: =INDEX(Constants!$E$18:$E$41,MATCH(I13&"#"&E13,Constants!$A$18:$A$41,0)) -> 1.42 | N13: =J13-L13 -> -0.1637 | O13: =K13-M13 -> 0.0267 | P13: =SQRT((N13/Constants!$B$8)^2+(O13/Constants!$B$9)^2) -> 0.96795942 | Q13: =IF(P13<=1.05,"Yes","No") -> Yes | R13: Inferred: level 1 before @b7874bc (all hits fit 2-3-2) | W13: 70 | X13: =Constants!$B$8*COS(RADIANS(W13)) -> 0.058998475 | Y13: =Constants!$B$9*SIN(RADIANS(W13)) -> 0.13155697
A14: 7 | B14: 46300.157 | C14: =(B14-INDEX(Rounds!$C:$C,MATCH(A14,Rounds!$A:$A,0)))*86400 -> 283.46 | D14: mole_hit | E14: 5 | F14: 100 | G14: 100 | H14: 1 | I14: 2-3-2 | J14: 0.421 | K14: 1.6427 | L14: =INDEX(Constants!$D$18:$D$41,MATCH(I14&"#"&E14,Constants!$A$18:$A$41,0)) -> 0.5 | M14: =INDEX(Constants!$E$18:$E$41,MATCH(I14&"#"&E14,Constants!$A$18:$A$41,0)) -> 1.74 | N14: =J14-L14 -> -0.079 | O14: =K14-M14 -> -0.0973 | P14: =SQRT((N14/Constants!$B$8)^2+(O14/Constants!$B$9)^2) -> 0.83232352 | Q14: =IF(P14<=1.05,"Yes","No") -> Yes | R14: Inferred: level 1 before @b7874bc (all hits fit 2-3-2) | W14: 80 | X14: =Constants!$B$8*COS(RADIANS(W14)) -> 0.029954311 | Y14: =Constants!$B$9*SIN(RADIANS(W14)) -> 0.13787309
A15: 7 | B15: 46300.157 | C15: =(B15-INDEX(Rounds!$C:$C,MATCH(A15,Rounds!$A:$A,0)))*86400 -> 285.946 | D15: mole_hit | E15: 6 | F15: 100 | G15: 200 | H15: 1 | I15: 2-3-2 | J15: 0.8287 | K15: 1.7318 | L15: =INDEX(Constants!$D$18:$D$41,MATCH(I15&"#"&E15,Constants!$A$18:$A$41,0)) -> 1 | M15: =INDEX(Constants!$E$18:$E$41,MATCH(I15&"#"&E15,Constants!$A$18:$A$41,0)) -> 1.74 | N15: =J15-L15 -> -0.1713 | O15: =K15-M15 -> -0.0082 | P15: =SQRT((N15/Constants!$B$8)^2+(O15/Constants!$B$9)^2) -> 0.9947693 | Q15: =IF(P15<=1.05,"Yes","No") -> Yes | R15: Inferred: level 1 before @b7874bc (all hits fit 2-3-2) | W15: 90 | X15: =Constants!$B$8*COS(RADIANS(W15)) -> 1.0562579e-17 | Y15: =Constants!$B$9*SIN(RADIANS(W15)) -> 0.14
A16: 7 | B16: 46300.157 | C16: =(B16-INDEX(Rounds!$C:$C,MATCH(A16,Rounds!$A:$A,0)))*86400 -> 288.596 | D16: king_hit | E16: 4 | F16: 300 | G16: 500 | H16: 1 | I16: 2-3-2 | J16: 1.2034 | K16: 1.5443 | L16: =INDEX(Constants!$D$18:$D$41,MATCH(I16&"#"&E16,Constants!$A$18:$A$41,0)) -> 1.25 | M16: =INDEX(Constants!$E$18:$E$41,MATCH(I16&"#"&E16,Constants!$A$18:$A$41,0)) -> 1.42 | N16: =J16-L16 -> -0.0466 | O16: =K16-M16 -> 0.1243 | P16: =SQRT((N16/Constants!$B$8)^2+(O16/Constants!$B$9)^2) -> 0.92804557 | Q16: =IF(P16<=1.05,"Yes","No") -> Yes | R16: Inferred: level 1 before @b7874bc (all hits fit 2-3-2) | W16: 100 | X16: =Constants!$B$8*COS(RADIANS(W16)) -> -0.029954311 | Y16: =Constants!$B$9*SIN(RADIANS(W16)) -> 0.13787309
A17: 8 | B17: 46300.157 | C17: =(B17-INDEX(Rounds!$C:$C,MATCH(A17,Rounds!$A:$A,0)))*86400 -> 4.8849998 | D17: mole_hit | E17: 5 | F17: 100 | G17: 100 | H17: 1 | I17: 2-3-2 | J17: 0.3412 | K17: 1.7562 | L17: =INDEX(Constants!$D$18:$D$41,MATCH(I17&"#"&E17,Constants!$A$18:$A$41,0)) -> 0.5 | M17: =INDEX(Constants!$E$18:$E$41,MATCH(I17&"#"&E17,Constants!$A$18:$A$41,0)) -> 1.74 | N17: =J17-L17 -> -0.1588 | O17: =K17-M17 -> 0.0162 | P17: =SQRT((N17/Constants!$B$8)^2+(O17/Constants!$B$9)^2) -> 0.92782369 | Q17: =IF(P17<=1.05,"Yes","No") -> Yes | R17: Inferred: level 1 before @b7874bc (all hits fit 2-3-2) | W17: 110 | X17: =Constants!$B$8*COS(RADIANS(W17)) -> -0.058998475 | Y17: =Constants!$B$9*SIN(RADIANS(W17)) -> 0.13155697
A18: 8 | B18: 46300.158 | C18: =(B18-INDEX(Rounds!$C:$C,MATCH(A18,Rounds!$A:$A,0)))*86400 -> 31.328 | D18: mole_hit | E18: 3 | F18: 100 | G18: 200 | H18: 1 | I18: 2-3-2 | J18: 0.5843 | K18: 1.4119 | L18: =INDEX(Constants!$D$18:$D$41,MATCH(I18&"#"&E18,Constants!$A$18:$A$41,0)) -> 0.75 | M18: =INDEX(Constants!$E$18:$E$41,MATCH(I18&"#"&E18,Constants!$A$18:$A$41,0)) -> 1.42 | N18: =J18-L18 -> -0.1657 | O18: =K18-M18 -> -0.0081 | P18: =SQRT((N18/Constants!$B$8)^2+(O18/Constants!$B$9)^2) -> 0.96232054 | Q18: =IF(P18<=1.05,"Yes","No") -> Yes | R18: Inferred: level 1 before @b7874bc (all hits fit 2-3-2) | W18: 120 | X18: =Constants!$B$8*COS(RADIANS(W18)) -> -0.08625 | Y18: =Constants!$B$9*SIN(RADIANS(W18)) -> 0.12124356
A19: 8 | B19: 46300.158 | C19: =(B19-INDEX(Rounds!$C:$C,MATCH(A19,Rounds!$A:$A,0)))*86400 -> 33.947 | D19: king_hit | E19: 0 | F19: 300 | G19: 500 | H19: 1 | I19: 2-3-2 | J19: 0.5195 | K19: 1.2369 | L19: =INDEX(Constants!$D$18:$D$41,MATCH(I19&"#"&E19,Constants!$A$18:$A$41,0)) -> 0.5 | M19: =INDEX(Constants!$E$18:$E$41,MATCH(I19&"#"&E19,Constants!$A$18:$A$41,0)) -> 1.1 | N19: =J19-L19 -> 0.0195 | O19: =K19-M19 -> 0.1369 | P19: =SQRT((N19/Constants!$B$8)^2+(O19/Constants!$B$9)^2) -> 0.98436955 | Q19: =IF(P19<=1.05,"Yes","No") -> Yes | R19: Inferred: level 1 before @b7874bc (all hits fit 2-3-2) | W19: 130 | X19: =Constants!$B$8*COS(RADIANS(W19)) -> -0.11088086 | Y19: =Constants!$B$9*SIN(RADIANS(W19)) -> 0.10724622
A20: 8 | B20: 46300.158 | C20: =(B20-INDEX(Rounds!$C:$C,MATCH(A20,Rounds!$A:$A,0)))*86400 -> 45.187001 | D20: mole_hit | E20: 2 | F20: 100 | G20: 600 | H20: 2 | I20: 2-3-2 | J20: 0.401 | K20: 1.4569 | L20: =INDEX(Constants!$D$18:$D$41,MATCH(I20&"#"&E20,Constants!$A$18:$A$41,0)) -> 0.25 | M20: =INDEX(Constants!$E$18:$E$41,MATCH(I20&"#"&E20,Constants!$A$18:$A$41,0)) -> 1.42 | N20: =J20-L20 -> 0.151 | O20: =K20-M20 -> 0.0369 | P20: =SQRT((N20/Constants!$B$8)^2+(O20/Constants!$B$9)^2) -> 0.9141822 | Q20: =IF(P20<=1.05,"Yes","No") -> Yes | R20: Inferred: level 1 before @b7874bc (all hits fit 2-3-2) | W20: 140 | X20: =Constants!$B$8*COS(RADIANS(W20)) -> -0.13214267 | Y20: =Constants!$B$9*SIN(RADIANS(W20)) -> 0.089990265
A21: 8 | B21: 46300.158 | C21: =(B21-INDEX(Rounds!$C:$C,MATCH(A21,Rounds!$A:$A,0)))*86400 -> 54.804 | D21: mole_hit | E21: 3 | F21: 200 | G21: 800 | H21: 2 | I21: 3-2-3 | J21: 0.3881 | K21: 1.524 | L21: =INDEX(Constants!$D$18:$D$41,MATCH(I21&"#"&E21,Constants!$A$18:$A$41,0)) -> 0.5 | M21: =INDEX(Constants!$E$18:$E$41,MATCH(I21&"#"&E21,Constants!$A$18:$A$41,0)) -> 1.42 | N21: =J21-L21 -> -0.1119 | O21: =K21-M21 -> 0.104 | P21: =SQRT((N21/Constants!$B$8)^2+(O21/Constants!$B$9)^2) -> 0.98622654 | Q21: =IF(P21<=1.05,"Yes","No") -> Yes | R21: 'Level up' log line | W21: 150 | X21: =Constants!$B$8*COS(RADIANS(W21)) -> -0.14938938 | Y21: =Constants!$B$9*SIN(RADIANS(W21)) -> 0.07
